[{"type":"subscriptions","channels":[{"name":"heartbeat","product_ids":["BTC-USD"]},{"name":"full","product_ids":["BTC-USD"]}]},{"order_id":"f74ede75-6b61-40de-8634-27c352018a1f","order_type":"limit","size":"0.0159332","price":"18865.4","client_oid":"05122000-0000-0000-0000-636fd32400cb","type":"received","side":"buy","product_id":"BTC-USD","time":"2022-09-26T04:01:04.537357Z","sequence":46725052889},{"price":"18865.4","order_id":"f74ede75-6b61-40de-8634-27c352018a1f","remaining_size":"0.0159332","type":"open","side":"buy","product_id":"BTC-USD","time":"2022-09-26T04:01:04.537357Z","sequence":46725052890},{"order_id":"d9ace326-5eb7-46df-85ad-7414e570f178","reason":"canceled","price":"19375.4","remaining_size":"0.0010706","type":"done","side":"sell","product_id":"BTC-USD","time":"2022-09-26T04:01:04.543196Z","sequence":46725052891},{"order_id":"951cd4f1-e262-4019-b52f-a8e9142e53f3","order_type":"limit","size":"0.00650938","price":"18865.4","client_oid":"15122000-0000-0000-0000-636fd323bda7","type":"received","side":"buy","product_id":"BTC-USD","time":"2022-09-26T04:01:04.600588Z","sequence":46725052892},{"price":"18865.4","order_id":"951cd4f1-e262-4019-b52f-a8e9142e53f3","remaining_size":"0.00650938","type":"open","side":"buy","product_id":"BTC-USD","time":"2022-09-26T04:01:04.600588Z","sequence":46725052893},{"order_id":"f506ce9f-6c6a-4633-8339-24b864e744fa","order_type":"limit","size":"0.0010547","price":"19247.17","client_oid":"b23d422f-64e1-4559-b065-b2a68379dc59","type":"received","side":"buy","product_id":"BTC-USD","time":"2022-09-26T04:01:04.601020Z","sequence":46725052894},{"trade_id":418306576,"maker_order_id":"5d198d02-6c59-44a0-a4c0-770bc8780beb","taker_order_id":"f506ce9f-6c6a-4633-8339-24b864e744fa","size":"0.0010547","price":"18866.1","type":"match","side":"sell","product_id":"BTC-USD","time":"2022-09-26T04:01:04.601020Z","sequence":46725052895},{"order_id":"f506ce9f-6c6a-4633-8339-24b864e744fa","reason":"filled","price":"19247.17","remaining_size":"0","type":"done","side":"buy","product_id":"BTC-USD","time":"2022-09-26T04:01:04.601020Z","sequence":46725052896},{"order_id":"38660804-604a-4249-ba2a-430bd3e34956","reason":"canceled","price":"18866.95","remaining_size":"0.01","type":"done","side":"sell","product_id":"BTC-USD","time":"2022-09-26T04:01:04.608418Z","sequence":46725052897},{"order_id":"f59b2f06-a9f7-4cc0-9de9-45924bec7a26","order_type":"limit","size":"0.02198","price":"18866.1","client_oid":"20220926-0000-0000-0001-000000213675","type":"received","side":"sell","product_id":"BTC-USD","time":"2022-09-26T04:01:04.609107Z","sequence":46725052898},{"price":"18866.1","order_id":"f59b2f06-a9f7-4cc0-9de9-45924bec7a26","remaining_size":"0.02198","type":"open","side":"sell","product_id":"BTC-USD","time":"2022-09-26T04:01:04.609107Z","sequence":46725052899},{"order_id":"f59b2f06-a9f7-4cc0-9de9-45924bec7a26","reason":"canceled","price":"18866.1","remaining_size":"0.02198","type":"done","side":"sell","product_id":"BTC-USD","time":"2022-09-26T04:01:04.613154Z","sequence":46725052900},{"order_id":"2fd6fea7-0f22-487e-8098-c4e91cdda391","reason":"canceled","price":"18865.4","remaining_size":"0.00602534","type":"done","side":"buy","product_id":"BTC-USD","time":"2022-09-26T04:01:04.615486Z","sequence":46725052901},{"order_id":"6f051cc4-58f0-4afa-bdc1-1c3f6fff44c7","order_type":"limit","size":"0.0010706","price":"19375.29","client_oid":"00000000-0000-0000-0005-e958faed545e","type":"received","side":"sell","product_id":"BTC-USD","time":"2022-09-26T04:01:04.615659Z","sequence":46725052902},{"price":"19375.29","order_id":"6f051cc4-58f0-4afa-bdc1-1c3f6fff44c7","remaining_size":"0.0010706","type":"open","side":"sell","product_id":"BTC-USD","time":"2022-09-26T04:01:04.615659Z","sequence":46725052903},{"order_id":"a00ed117-3634-4fd5-a6c9-c37767814079","order_type":"limit","size":"0.00254019","price":"18866.1","client_oid":"1e1e3b2e-8277-4c19-a171-e5e8058b1cd6","type":"received","side":"sell","product_id":"BTC-USD","time":"2022-09-26T04:01:04.616134Z","sequence":46725052904},{"price":"18866.1","order_id":"a00ed117-3634-4fd5-a6c9-c37767814079","remaining_size":"0.00254019","type":"open","side":"sell","product_id":"BTC-USD","time":"2022-09-26T04:01:04.616134Z","sequence":46725052905},{"order_id":"75178317-db1a-4df8-be07-78d16f02ba12","reason":"canceled","price":"18865.4","remaining_size":"0.00660483","type":"done","side":"buy","product_id":"BTC-USD","time":"2022-09-26T04:01:04.619986Z","sequence":46725052906},{"order_id":"768fd97b-7d80-41c0-8b97-f5c979213991","order_type":"limit","size":"0.01","price":"18866.96","client_oid":"c3309217-6ebf-46ab-8838-e35d696e2037","type":"received","side":"sell","product_id":"BTC-USD","time":"2022-09-26T04:01:04.620025Z","sequence":46725052907},{"price":"18866.96","order_id":"768fd97b-7d80-41c0-8b97-f5c979213991","remaining_size":"0.01","type":"open","side":"sell","product_id":"BTC-USD","time":"2022-09-26T04:01:04.620025Z","sequence":46725052908},{"order_id":"c2e6ed49-2367-4eaa-88d2-8f4c49b22d37","order_type":"limit","size":"0.00885873","price":"18865.4","client_oid":"15122000-0000-0000-0000-636fd323e260","type":"received","side":"buy","product_id":"BTC-USD","time":"2022-09-26T04:01:04.620275Z","sequence":46725052909},{"price":"18865.4","order_id":"c2e6ed49-2367-4eaa-88d2-8f4c49b22d37","remaining_size":"0.00885873","type":"open","side":"buy","product_id":"BTC-USD","time":"2022-09-26T04:01:04.620275Z","sequence":46725052910},{"order_id":"768fd97b-7d80-41c0-8b97-f5c979213991","reason":"canceled","price":"18866.96","remaining_size":"0.01","type":"done","side":"sell","product_id":"BTC-USD","time":"2022-09-26T04:01:04.627517Z","sequence":46725052911},{"order_id":"7e0afb73-c200-424a-b8f2-18ff68ae944d","order_type":"limit","size":"0.02198","price":"18866.1","client_oid":"20220926-0000-0000-0002-000000219322","type":"received","side":"sell","product_id":"BTC-USD","time":"2022-09-26T04:01:04.628102Z","sequence":46725052912},{"price":"18866.1","order_id":"7e0afb73-c200-424a-b8f2-18ff68ae944d","remaining_size":"0.02198","type":"open","side":"sell","product_id":"BTC-USD","time":"2022-09-26T04:01:04.628102Z","sequence":46725052913},{"order_id":"e9ce4e7d-29fd-409d-a185-2ec876cbde75","order_type":"limit","size":"0.00794155","price":"18865.4","client_oid":"15122000-0000-0000-0000-636fd323eee7","type":"received","side":"buy","product_id":"BTC-USD","time":"2022-09-26T04:01:04.632474Z","sequence":46725052914},{"price":"18865.4","order_id":"e9ce4e7d-29fd-409d-a185-2ec876cbde75","remaining_size":"0.00794155","type":"open","side":"buy","product_id":"BTC-USD","time":"2022-09-26T04:01:04.632474Z","sequence":46725052915},{"order_id":"951cd4f1-e262-4019-b52f-a8e9142e53f3","reason":"canceled","price":"18865.4","remaining_size":"0.00650938","type":"done","side":"buy","product_id":"BTC-USD","time":"2022-09-26T04:01:04.634690Z","sequence":46725052916},{"order_id":"c2e6ed49-2367-4eaa-88d2-8f4c49b22d37","reason":"canceled","price":"18865.4","remaining_size":"0.00885873","type":"done","side":"buy","product_id":"BTC-USD","time":"2022-09-26T04:01:04.640054Z","sequence":46725052917},{"order_id":"165ae51f-3f1f-4bf0-a923-2f91f03449db","reason":"canceled","price":"18864.12","remaining_size":"0.04741012","type":"done","side":"buy","product_id":"BTC-USD","time":"2022-09-26T04:01:04.678455Z","sequence":46725052918},{"order_id":"e3795c60-00bb-4eb6-a630-2dd8887aa960","order_type":"limit","size":"0.0057415","price":"18865.4","client_oid":"15122000-0000-0000-0000-636fd32400cb","type":"received","side":"buy","product_id":"BTC-USD","time":"2022-09-26T04:01:04.694509Z","sequence":46725052919},{"price":"18865.4","order_id":"e3795c60-00bb-4eb6-a630-2dd8887aa960","remaining_size":"0.0057415","type":"open","side":"buy","product_id":"BTC-USD","time":"2022-09-26T04:01:04.694509Z","sequence":46725052920},{"order_id":"080a4b26-0471-4815-81c0-c036f4539e61","order_type":"limit","size":"0.1","price":"18869.21","client_oid":"d7937884-3d4f-11ed-8b5d-abb0b41c20d0","type":"received","side":"sell","product_id":"BTC-USD","time":"2022-09-26T04:01:04.694673Z","sequence":46725052921},{"price":"18869.21","order_id":"080a4b26-0471-4815-81c0-c036f4539e61","remaining_size":"0.1","type":"open","side":"sell","product_id":"BTC-USD","time":"2022-09-26T04:01:04.694673Z","sequence":46725052922},{"order_id":"9d8a8918-d19d-4cab-bb16-e5f2800236eb","order_type":"limit","size":"0.1","price":"18862.96","client_oid":"d7935172-3d4f-11ed-8b5d-abb0b41c20d0","type":"received","side":"buy","product_id":"BTC-USD","time":"2022-09-26T04:01:04.694688Z","sequence":46725052923},{"price":"18862.96","order_id":"9d8a8918-d19d-4cab-bb16-e5f2800236eb","remaining_size":"0.1","type":"open","side":"buy","product_id":"BTC-USD","time":"2022-09-26T04:01:04.694688Z","sequence":46725052924},{"order_id":"f74ede75-6b61-40de-8634-27c352018a1f","reason":"canceled","price":"18865.4","remaining_size":"0.0159332","type":"done","side":"buy","product_id":"BTC-USD","time":"2022-09-26T04:01:04.702351Z","sequence":46725052925},{"order_id":"e9ce4e7d-29fd-409d-a185-2ec876cbde75","reason":"canceled","price":"18865.4","remaining_size":"0.00794155","type":"done","side":"buy","product_id":"BTC-USD","time":"2022-09-26T04:01:04.703429Z","sequence":46725052926},{"order_id":"e3795c60-00bb-4eb6-a630-2dd8887aa960","reason":"canceled","price":"18865.4","remaining_size":"0.0057415","type":"done","side":"buy","product_id":"BTC-USD","time":"2022-09-26T04:01:04.705512Z","sequence":46725052927},{"order_id":"dee4d69b-779f-4416-aa95-ea33a1b05ceb","order_type":"limit","size":"0.01246977","price":"18865.4","client_oid":"25122000-0000-0000-0000-636fd323bda7","type":"received","side":"buy","product_id":"BTC-USD","time":"2022-09-26T04:01:04.716641Z","sequence":46725052928},{"price":"18865.4","order_id":"dee4d69b-779f-4416-aa95-ea33a1b05ceb","remaining_size":"0.01246977","type":"open","side":"buy","product_id":"BTC-USD","time":"2022-09-26T04:01:04.716641Z","sequence":46725052929},{"order_id":"537f48cb-3e5f-4889-bd45-b3a45adef860","order_type":"limit","size":"0.0057415","price":"18865.4","client_oid":"25122000-0000-0000-0000-636fd323e260","type":"received","side":"buy","product_id":"BTC-USD","time":"2022-09-26T04:01:04.717030Z","sequence":46725052930},{"price":"18865.4","order_id":"537f48cb-3e5f-4889-bd45-b3a45adef860","remaining_size":"0.0057415","type":"open","side":"buy","product_id":"BTC-USD","time":"2022-09-26T04:01:04.717030Z","sequence":46725052931},{"order_id":"06bae66f-d6dc-443e-a1c1-7719da6c8171","order_type":"limit","size":"0.23726241","price":"18857.63","client_oid":"d79a0838-3d4f-11ed-8b5d-abb0b41c20d0","type":"received","side":"buy","product_id":"BTC-USD","time":"2022-09-26T04:01:04.733625Z","sequence":46725052932},{"price":"18857.63","order_id":"06bae66f-d6dc-443e-a1c1-7719da6c8171","remaining_size":"0.23726241","type":"open","side":"buy","product_id":"BTC-USD","time":"2022-09-26T04:01:04.733625Z","sequence":46725052933},{"order_id":"ce63df8f-65a3-44c8-a20f-a8dd95c0a3f4","order_type":"limit","size":"0.01407347","price":"18857.63","client_oid":"d799e126-3d4f-11ed-8b5d-abb0b41c20d0","type":"received","side":"buy","product_id":"BTC-USD","time":"2022-09-26T04:01:04.733791Z","sequence":46725052934},{"price":"18857.63","order_id":"ce63df8f-65a3-44c8-a20f-a8dd95c0a3f4","remaining_size":"0.01407347","type":"open","side":"buy","product_id":"BTC-USD","time":"2022-09-26T04:01:04.733791Z","sequence":46725052935},{"order_id":"04a5f48c-fede-4279-a980-d88ac010a034","order_type":"limit","size":"0.15689832","price":"18876.98","client_oid":"d79a2f4c-3d4f-11ed-8b5d-abb0b41c20d0","type":"received","side":"sell","product_id":"BTC-USD","time":"2022-09-26T04:01:04.738312Z","sequence":46725052936},{"price":"18876.98","order_id":"04a5f48c-fede-4279-a980-d88ac010a034","remaining_size":"0.15689832","type":"open","side":"sell","product_id":"BTC-USD","time":"2022-09-26T04:01:04.738312Z","sequence":46725052937},{"order_id":"570cf4b6-36d3-4474-a49c-87d3f111e0fc","order_type":"limit","size":"0.15897858","price":"18856.22","client_oid":"d79a083a-3d4f-11ed-8b5d-abb0b41c20d0","type":"received","side":"buy","product_id":"BTC-USD","time":"2022-09-26T04:01:04.738852Z","sequence":46725052938},{"price":"18856.22","order_id":"570cf4b6-36d3-4474-a49c-87d3f111e0fc","remaining_size":"0.15897858","type":"open","side":"buy","product_id":"BTC-USD","time":"2022-09-26T04:01:04.738852Z","sequence":46725052939},{"order_id":"7e0afb73-c200-424a-b8f2-18ff68ae944d","reason":"canceled","price":"18866.1","remaining_size":"0.02198","type":"done","side":"sell","product_id":"BTC-USD","time":"2022-09-26T04:01:04.760406Z","sequence":46725052940},{"order_id":"ceda3d19-8467-469d-8f09-1ff5f305bbf6","order_type":"limit","size":"0.00550263","price":"18865.4","client_oid":"25122000-0000-0000-0000-636fd323eee7","type":"received","side":"buy","product_id":"BTC-USD","time":"2022-09-26T04:01:04.776238Z","sequence":46725052941},{"price":"18865.4","order_id":"ceda3d19-8467-469d-8f09-1ff5f305bbf6","remaining_size":"0.00550263","type":"open","side":"buy","product_id":"BTC-USD","time":"2022-09-26T04:01:04.776238Z","sequence":46725052942},{"order_id":"0d6c37ad-253d-4321-9c53-c69bdd6f6a1e","order_type":"limit","size":"0.04397419","price":"18864.15","client_oid":"d663b47b-886a-5517-1279-a8e50a11694c","type":"received","side":"buy","product_id":"BTC-USD","time":"2022-09-26T04:01:04.794235Z","sequence":46725052943},{"price":"18864.15","order_id":"0d6c37ad-253d-4321-9c53-c69bdd6f6a1e","remaining_size":"0.04397419","type":"open","side":"buy","product_id":"BTC-USD","time":"2022-09-26T04:01:04.794235Z","sequence":46725052944},{"order_id":"ee5f8cc9-9b83-4056-afd4-f55d98103d6d","order_type":"limit","size":"0.02198","price":"18866.1","client_oid":"20220926-0000-0000-0005-000000220049","type":"received","side":"sell","product_id":"BTC-USD","time":"2022-09-26T04:01:04.933111Z","sequence":46725052945},{"price":"18866.1","order_id":"ee5f8cc9-9b83-4056-afd4-f55d98103d6d","remaining_size":"0.02198","type":"open","side":"sell","product_id":"BTC-USD","time":"2022-09-26T04:01:04.933111Z","sequence":46725052946},{"order_id":"ee5f8cc9-9b83-4056-afd4-f55d98103d6d","reason":"canceled","price":"18866.1","remaining_size":"0.02198","type":"done","side":"sell","product_id":"BTC-USD","time":"2022-09-26T04:01:04.941502Z","sequence":46725052947},{"order_id":"537f48cb-3e5f-4889-bd45-b3a45adef860","reason":"canceled","price":"18865.4","remaining_size":"0.0057415","type":"done","side":"buy","product_id":"BTC-USD","time":"2022-09-26T04:01:04.941514Z","sequence":46725052948},{"order_id":"552178dd-0a07-4366-bb30-f9c1515c64d6","order_type":"limit","size":"0.00620012","price":"18865.4","client_oid":"25122000-0000-0000-0000-636fd32400cb","type":"received","side":"buy","product_id":"BTC-USD","time":"2022-09-26T04:01:04.954160Z","sequence":46725052949},{"price":"18865.4","order_id":"552178dd-0a07-4366-bb30-f9c1515c64d6","remaining_size":"0.00620012","type":"open","side":"buy","product_id":"BTC-USD","time":"2022-09-26T04:01:04.954160Z","sequence":46725052950},{"order_id":"ceda3d19-8467-469d-8f09-1ff5f305bbf6","reason":"canceled","price":"18865.4","remaining_size":"0.00550263","type":"done","side":"buy","product_id":"BTC-USD","time":"2022-09-26T04:01:05.017734Z","sequence":46725052951},{"order_id":"552178dd-0a07-4366-bb30-f9c1515c64d6","reason":"canceled","price":"18865.4","remaining_size":"0.00620012","type":"done","side":"buy","product_id":"BTC-USD","time":"2022-09-26T04:01:05.034368Z","sequence":46725052952},{"order_id":"78f7ed89-9674-4017-bee6-bb10ad203062","order_type":"limit","size":"0.004","price":"18866.1","client_oid":"059620be-0beb-42c5-808a-df2abc348938","type":"received","side":"sell","product_id":"BTC-USD","time":"2022-09-26T04:01:05.038851Z","sequence":46725052953},{"price":"18866.1","order_id":"78f7ed89-9674-4017-bee6-bb10ad203062","remaining_size":"0.004","type":"open","side":"sell","product_id":"BTC-USD","time":"2022-09-26T04:01:05.038851Z","sequence":46725052954},{"order_id":"83d84a29-1896-4af7-8e3f-a3d0a2b0485c","order_type":"limit","size":"0.02","price":"18868.07","client_oid":"c2b03681-2939-4794-a017-6d06ecc83d02","type":"received","side":"sell","product_id":"BTC-USD","time":"2022-09-26T04:01:05.038893Z","sequence":46725052955},{"price":"18868.07","order_id":"83d84a29-1896-4af7-8e3f-a3d0a2b0485c","remaining_size":"0.02","type":"open","side":"sell","product_id":"BTC-USD","time":"2022-09-26T04:01:05.038893Z","sequence":46725052956},{"order_id":"050bb16a-9d1c-442f-ac68-b867194c7b27","order_type":"limit","size":"0.01079796","price":"18865.4","client_oid":"35122000-0000-0000-0000-636fd323bda7","type":"received","side":"buy","product_id":"BTC-USD","time":"2022-09-26T04:01:05.038907Z","sequence":46725052957},{"price":"18865.4","order_id":"050bb16a-9d1c-442f-ac68-b867194c7b27","remaining_size":"0.01079796","type":"open","side":"buy","product_id":"BTC-USD","time":"2022-09-26T04:01:05.038907Z","sequence":46725052958},{"order_id":"7a0132c9-5d6c-4aac-a565-bdcf856fefb1","order_type":"limit","size":"0.004","price":"18865.41","client_oid":"56a56620-7902-4fd0-904a-28fdf5589dae","type":"received","side":"buy","product_id":"BTC-USD","time":"2022-09-26T04:01:05.039165Z","sequence":46725052959},{"price":"18865.41","order_id":"7a0132c9-5d6c-4aac-a565-bdcf856fefb1","remaining_size":"0.004","type":"open","side":"buy","product_id":"BTC-USD","time":"2022-09-26T04:01:05.039165Z","sequence":46725052960},{"order_id":"c9085fc1-9764-42b0-9336-28a901b495f3","order_type":"limit","size":"0.015","price":"18866.09","client_oid":"f889fe8c-c0b3-44a0-9f58-758011867e92","type":"received","side":"buy","product_id":"BTC-USD","time":"2022-09-26T04:01:05.039299Z","sequence":46725052961},{"price":"18866.09","order_id":"c9085fc1-9764-42b0-9336-28a901b495f3","remaining_size":"0.015","type":"open","side":"buy","product_id":"BTC-USD","time":"2022-09-26T04:01:05.039299Z","sequence":46725052962},{"order_id":"6810584e-bfe6-4626-b787-32f13da8fa50","order_type":"limit","size":"0.01","price":"18864.75","client_oid":"1e7c28c7-2e8f-4dfb-b096-b52e5b484c61","type":"received","side":"buy","product_id":"BTC-USD","time":"2022-09-26T04:01:05.039417Z","sequence":46725052963},{"price":"18864.75","order_id":"6810584e-bfe6-4626-b787-32f13da8fa50","remaining_size":"0.01","type":"open","side":"buy","product_id":"BTC-USD","time":"2022-09-26T04:01:05.039417Z","sequence":46725052964},{"order_id":"af2a667d-872c-483f-b653-0dcbb42df9d3","order_type":"limit","size":"0.01","price":"18866.95","client_oid":"01a55241-b73b-4ef2-b07c-18ca788c3c84","type":"received","side":"sell","product_id":"BTC-USD","time":"2022-09-26T04:01:05.039431Z","sequence":46725052965},{"price":"18866.95","order_id":"af2a667d-872c-483f-b653-0dcbb42df9d3","remaining_size":"0.01","type":"open","side":"sell","product_id":"BTC-USD","time":"2022-09-26T04:01:05.039431Z","sequence":46725052966},{"order_id":"7a0132c9-5d6c-4aac-a565-bdcf856fefb1","reason":"canceled","price":"18865.41","remaining_size":"0.004","type":"done","side":"buy","product_id":"BTC-USD","time":"2022-09-26T04:01:05.046490Z","sequence":46725052967},{"order_id":"dee4d69b-779f-4416-aa95-ea33a1b05ceb","reason":"canceled","price":"18865.4","remaining_size":"0.01246977","type":"done","side":"buy","product_id":"BTC-USD","time":"2022-09-26T04:01:05.047472Z","sequence":46725052968},{"order_id":"d9fa6263-3546-49e0-a627-7635b6fc3e33","reason":"canceled","price":"18870.14","remaining_size":"0.02007258","type":"done","side":"sell","product_id":"BTC-USD","time":"2022-09-26T04:01:05.049375Z","sequence":46725052969},{"order_id":"050bb16a-9d1c-442f-ac68-b867194c7b27","reason":"canceled","price":"18865.4","remaining_size":"0.01079796","type":"done","side":"buy","product_id":"BTC-USD","time":"2022-09-26T04:01:05.050907Z","sequence":46725052970},{"order_id":"fcabe18b-f2a0-4c9b-b9a3-cfe95ec06b59","order_type":"limit","size":"0.06359147","price":"18856.23","client_oid":"eaa474fd-789f-41ff-ac5b-720a48a07346","type":"received","side":"buy","product_id":"BTC-USD","time":"2022-09-26T04:01:05.051430Z","sequence":46725052971},{"price":"18856.23","order_id":"fcabe18b-f2a0-4c9b-b9a3-cfe95ec06b59","remaining_size":"0.06359147","type":"open","side":"buy","product_id":"BTC-USD","time":"2022-09-26T04:01:05.051430Z","sequence":46725052972},{"order_id":"f0075488-c491-426d-8c2c-0d52de907e08","order_type":"limit","size":"0.004","price":"18865.38","client_oid":"9bc91419-ae4e-4e74-929c-21cdd003b694","type":"received","side":"buy","product_id":"BTC-USD","time":"2022-09-26T04:01:05.051570Z","sequence":46725052973},{"price":"18865.38","order_id":"f0075488-c491-426d-8c2c-0d52de907e08","remaining_size":"0.004","type":"open","side":"buy","product_id":"BTC-USD","time":"2022-09-26T04:01:05.051570Z","sequence":46725052974},{"order_id":"a11a2e85-1ce2-48cd-bcbe-0bd807840a3d","order_type":"limit","size":"0.02198","price":"18866.1","client_oid":"20220926-0000-0000-0001-000000213678","type":"received","side":"sell","product_id":"BTC-USD","time":"2022-09-26T04:01:05.051802Z","sequence":46725052975},{"price":"18866.1","order_id":"a11a2e85-1ce2-48cd-bcbe-0bd807840a3d","remaining_size":"0.02198","type":"open","side":"sell","product_id":"BTC-USD","time":"2022-09-26T04:01:05.051802Z","sequence":46725052976},{"order_id":"78f7ed89-9674-4017-bee6-bb10ad203062","reason":"canceled","price":"18866.1","remaining_size":"0.004","type":"done","side":"sell","product_id":"BTC-USD","time":"2022-09-26T04:01:05.052156Z","sequence":46725052977},{"order_id":"83d84a29-1896-4af7-8e3f-a3d0a2b0485c","reason":"canceled","price":"18868.07","remaining_size":"0.02","type":"done","side":"sell","product_id":"BTC-USD","time":"2022-09-26T04:01:05.052179Z","sequence":46725052978},{"order_id":"a11a2e85-1ce2-48cd-bcbe-0bd807840a3d","reason":"canceled","price":"18866.1","remaining_size":"0.02198","type":"done","side":"sell","product_id":"BTC-USD","time":"2022-09-26T04:01:05.056191Z","sequence":46725052979},{"order_id":"edba41e0-34b5-4d0e-97fc-a05e01fda5bb","order_type":"limit","size":"0.02131402","price":"18865.44","client_oid":"35122000-0000-0000-0000-636fd323e260","type":"received","side":"buy","product_id":"BTC-USD","time":"2022-09-26T04:01:05.058954Z","sequence":46725052980},{"price":"18865.44","order_id":"edba41e0-34b5-4d0e-97fc-a05e01fda5bb","remaining_size":"0.02131402","type":"open","side":"buy","product_id":"BTC-USD","time":"2022-09-26T04:01:05.058954Z","sequence":46725052981},{"order_id":"8a9323ab-4d05-464d-bfda-2e079d0bff6f","order_type":"limit","size":"0.00532339","price":"18866.1","client_oid":"35122000-0000-0000-0000-636fd323eee7","type":"received","side":"sell","product_id":"BTC-USD","time":"2022-09-26T04:01:05.058996Z","sequence":46725052982},{"price":"18866.1","order_id":"8a9323ab-4d05-464d-bfda-2e079d0bff6f","remaining_size":"0.00532339","type":"open","side":"sell","product_id":"BTC-USD","time":"2022-09-26T04:01:05.058996Z","sequence":46725052983},{"order_id":"eb25b6db-743d-4174-bba4-27ae9378143d","order_type":"limit","size":"0.02","price":"18867.94","client_oid":"e5693cd1-62cf-4384-a5e6-c4ecd9656112","type":"received","side":"sell","product_id":"BTC-USD","time":"2022-09-26T04:01:05.059099Z","sequence":46725052984},{"price":"18867.94","order_id":"eb25b6db-743d-4174-bba4-27ae9378143d","remaining_size":"0.02","type":"open","side":"sell","product_id":"BTC-USD","time":"2022-09-26T04:01:05.059099Z","sequence":46725052985},{"order_id":"8b42fdf3-b868-4678-9795-5f99e25a09ac","order_type":"limit","size":"0.00605906","price":"18866.1","client_oid":"35122000-0000-0000-0000-636fd32400cb","type":"received","side":"sell","product_id":"BTC-USD","time":"2022-09-26T04:01:05.063055Z","sequence":46725052986},{"price":"18866.1","order_id":"8b42fdf3-b868-4678-9795-5f99e25a09ac","remaining_size":"0.00605906","type":"open","side":"sell","product_id":"BTC-USD","time":"2022-09-26T04:01:05.063055Z","sequence":46725052987},{"order_id":"44f3d0ae-4697-4eee-bce4-dbfdc5d56866","order_type":"limit","size":"0.01","price":"18864.76","client_oid":"ac169c92-e9b1-49d5-94cc-63c05e0b8c26","type":"received","side":"buy","product_id":"BTC-USD","time":"2022-09-26T04:01:05.063334Z","sequence":46725052988},{"price":"18864.76","order_id":"44f3d0ae-4697-4eee-bce4-dbfdc5d56866","remaining_size":"0.01","type":"open","side":"buy","product_id":"BTC-USD","time":"2022-09-26T04:01:05.063334Z","sequence":46725052989},{"order_id":"af2a667d-872c-483f-b653-0dcbb42df9d3","reason":"canceled","price":"18866.95","remaining_size":"0.01","type":"done","side":"sell","product_id":"BTC-USD","time":"2022-09-26T04:01:05.063622Z","sequence":46725052990},{"order_id":"8a9323ab-4d05-464d-bfda-2e079d0bff6f","reason":"canceled","price":"18866.1","remaining_size":"0.00532339","type":"done","side":"sell","product_id":"BTC-USD","time":"2022-09-26T04:01:05.065912Z","sequence":46725052991},{"order_id":"edba41e0-34b5-4d0e-97fc-a05e01fda5bb","reason":"canceled","price":"18865.44","remaining_size":"0.02131402","type":"done","side":"buy","product_id":"BTC-USD","time":"2022-09-26T04:01:05.066490Z","sequence":46725052992},{"order_id":"6810584e-bfe6-4626-b787-32f13da8fa50","reason":"canceled","price":"18864.75","remaining_size":"0.01","type":"done","side":"buy","product_id":"BTC-USD","time":"2022-09-26T04:01:05.067569Z","sequence":46725052993},{"order_id":"cb955f0b-68b6-4490-9af7-c4ed42d0c51e","reason":"canceled","price":"18863.55","remaining_size":"0.01504935","type":"done","side":"buy","product_id":"BTC-USD","time":"2022-09-26T04:01:05.069154Z","sequence":46725052994},{"order_id":"d9cfd2d8-61c6-42df-b18c-18e3ff96814b","order_type":"limit","size":"0.02198","price":"18866.1","client_oid":"20220926-0000-0000-0002-000000219324","type":"received","side":"sell","product_id":"BTC-USD","time":"2022-09-26T04:01:05.071547Z","sequence":46725052995},{"price":"18866.1","order_id":"d9cfd2d8-61c6-42df-b18c-18e3ff96814b","remaining_size":"0.02198","type":"open","side":"sell","product_id":"BTC-USD","time":"2022-09-26T04:01:05.071547Z","sequence":46725052996},{"order_id":"44f3d0ae-4697-4eee-bce4-dbfdc5d56866","reason":"canceled","price":"18864.76","remaining_size":"0.01","type":"done","side":"buy","product_id":"BTC-USD","time":"2022-09-26T04:01:05.071590Z","sequence":46725052997},{"order_id":"d9cfd2d8-61c6-42df-b18c-18e3ff96814b","reason":"canceled","price":"18866.1","remaining_size":"0.02198","type":"done","side":"sell","product_id":"BTC-USD","time":"2022-09-26T04:01:05.074738Z","sequence":46725052998},{"order_id":"2eec58d3-ccc7-4a74-b88e-548db91aec3a","order_type":"limit","size":"0.00527346","price":"18866.09","client_oid":"45122000-0000-0000-0000-636fd323e260","type":"received","side":"buy","product_id":"BTC-USD","time":"2022-09-26T04:01:05.075781Z","sequence":46725052999},{"price":"18866.09","order_id":"2eec58d3-ccc7-4a74-b88e-548db91aec3a","remaining_size":"0.00527346","type":"open","side":"buy","product_id":"BTC-USD","time":"2022-09-26T04:01:05.075781Z","sequence":46725053000},{"order_id":"e87a1415-4bc3-4d92-b652-7caa011f0e8b","order_type":"limit","size":"0.01","price":"18866.94","client_oid":"9b661ae7-2708-4879-9235-c076f450be3a","type":"received","side":"sell","product_id":"BTC-USD","time":"2022-09-26T04:01:05.075801Z","sequence":46725053001},{"price":"18866.94","order_id":"e87a1415-4bc3-4d92-b652-7caa011f0e8b","remaining_size":"0.01","type":"open","side":"sell","product_id":"BTC-USD","time":"2022-09-26T04:01:05.075801Z","sequence":46725053002},{"order_id":"eb25b6db-743d-4174-bba4-27ae9378143d","reason":"canceled","price":"18867.94","remaining_size":"0.02","type":"done","side":"sell","product_id":"BTC-USD","time":"2022-09-26T04:01:05.080005Z","sequence":46725053003},{"order_id":"fdeb878b-0a1c-49fe-b233-523322d6a784","order_type":"limit","size":"0.01504935","price":"18863.55","client_oid":"d7cf2655-3d4f-11ed-8a20-0aa09ad95c5f","type":"received","side":"buy","product_id":"BTC-USD","time":"2022-09-26T04:01:05.083515Z","sequence":46725053004},{"price":"18863.55","order_id":"fdeb878b-0a1c-49fe-b233-523322d6a784","remaining_size":"0.01504935","type":"open","side":"buy","product_id":"BTC-USD","time":"2022-09-26T04:01:05.083515Z","sequence":46725053005},{"order_id":"e87a1415-4bc3-4d92-b652-7caa011f0e8b","reason":"canceled","price":"18866.94","remaining_size":"0.01","type":"done","side":"sell","product_id":"BTC-USD","time":"2022-09-26T04:01:05.084012Z","sequence":46725053006},{"order_id":"8b42fdf3-b868-4678-9795-5f99e25a09ac","reason":"canceled","price":"18866.1","remaining_size":"0.00605906","type":"done","side":"sell","product_id":"BTC-USD","time":"2022-09-26T04:01:05.084341Z","sequence":46725053007},{"order_id":"2eec58d3-ccc7-4a74-b88e-548db91aec3a","reason":"canceled","price":"18866.09","remaining_size":"0.00527346","type":"done","side":"buy","product_id":"BTC-USD","time":"2022-09-26T04:01:05.084555Z","sequence":46725053008},{"order_id":"a6e8b702-24a7-4d67-bfde-b16caec608bc","reason":"canceled","price":"18863.69","remaining_size":"0.01929718","type":"done","side":"buy","product_id":"BTC-USD","time":"2022-09-26T04:01:05.089977Z","sequence":46725053009},{"order_id":"6e40c1a0-08b5-465a-9b2e-07f43b6632b0","order_type":"limit","size":"0.00636511","price":"18866.1","client_oid":"55122000-0000-0000-0000-636fd323bda7","type":"received","side":"sell","product_id":"BTC-USD","time":"2022-09-26T04:01:05.092273Z","sequence":46725053010},{"price":"18866.1","order_id":"6e40c1a0-08b5-465a-9b2e-07f43b6632b0","remaining_size":"0.00636511","type":"open","side":"sell","product_id":"BTC-USD","time":"2022-09-26T04:01:05.092273Z","sequence":46725053011},{"order_id":"28e33b0d-6dbc-4888-8977-dcf976f938de","order_type":"limit","size":"0.00527346","price":"18866.09","client_oid":"55122000-0000-0000-0000-636fd32400cb","type":"received","side":"buy","product_id":"BTC-USD","time":"2022-09-26T04:01:05.097067Z","sequence":46725053012},{"price":"18866.09","order_id":"28e33b0d-6dbc-4888-8977-dcf976f938de","remaining_size":"0.00527346","type":"open","side":"buy","product_id":"BTC-USD","time":"2022-09-26T04:01:05.097067Z","sequence":46725053013},{"order_id":"ff9c1f06-c10e-4e6c-b9e7-127d1058bbae","order_type":"limit","size":"0.02198","price":"18866.1","client_oid":"20220926-0000-0000-0003-000000211631","type":"received","side":"sell","product_id":"BTC-USD","time":"2022-09-26T04:01:05.097115Z","sequence":46725053014},{"price":"18866.1","order_id":"ff9c1f06-c10e-4e6c-b9e7-127d1058bbae","remaining_size":"0.02198","type":"open","side":"sell","product_id":"BTC-USD","time":"2022-09-26T04:01:05.097115Z","sequence":46725053015},{"order_id":"b4de748d-8509-402c-8061-b01eae3ba0aa","order_type":"limit","size":"0.02007258","price":"18870.14","client_oid":"d7d11ceb-3d4f-11ed-8a20-0aa09ad95c5f","type":"received","side":"sell","product_id":"BTC-USD","time":"2022-09-26T04:01:05.097165Z","sequence":46725053016},{"price":"18870.14","order_id":"b4de748d-8509-402c-8061-b01eae3ba0aa","remaining_size":"0.02007258","type":"open","side":"sell","product_id":"BTC-USD","time":"2022-09-26T04:01:05.097165Z","sequence":46725053017},{"order_id":"ae36aa6f-7e75-4748-a6e3-e1f98ced0bc1","order_type":"limit","size":"0.01972661","price":"18863.8","client_oid":"00000000-0000-0000-0005-e958faed546f","type":"received","side":"buy","product_id":"BTC-USD","time":"2022-09-26T04:01:05.097532Z","sequence":46725053018},{"price":"18863.8","order_id":"ae36aa6f-7e75-4748-a6e3-e1f98ced0bc1","remaining_size":"0.01972661","type":"open","side":"buy","product_id":"BTC-USD","time":"2022-09-26T04:01:05.097532Z","sequence":46725053019},{"order_id":"ff9c1f06-c10e-4e6c-b9e7-127d1058bbae","reason":"canceled","price":"18866.1","remaining_size":"0.02198","type":"done","side":"sell","product_id":"BTC-USD","time":"2022-09-26T04:01:05.102716Z","sequence":46725053020},{"order_id":"28e33b0d-6dbc-4888-8977-dcf976f938de","reason":"canceled","price":"18866.09","remaining_size":"0.00527346","type":"done","side":"buy","product_id":"BTC-USD","time":"2022-09-26T04:01:05.104425Z","sequence":46725053021},{"order_id":"6e40c1a0-08b5-465a-9b2e-07f43b6632b0","reason":"canceled","price":"18866.1","remaining_size":"0.00636511","type":"done","side":"sell","product_id":"BTC-USD","time":"2022-09-26T04:01:05.104569Z","sequence":46725053022},{"order_id":"4b8e0467-12a3-424b-98af-5d9a47b9c3ea","order_type":"limit","size":"0.06908114","price":"18848.73","client_oid":"193a34c1-ad96-b166-4154-412009938526","type":"received","side":"buy","product_id":"BTC-USD","time":"2022-09-26T04:01:05.105438Z","sequence":46725053023},{"price":"18848.73","order_id":"4b8e0467-12a3-424b-98af-5d9a47b9c3ea","remaining_size":"0.06908114","type":"open","side":"buy","product_id":"BTC-USD","time":"2022-09-26T04:01:05.105438Z","sequence":46725053024},{"order_id":"6c2bc33c-2638-4846-bade-a4fc0c44ea3b","order_type":"limit","size":"0.00501734","price":"18866.1","client_oid":"65122000-0000-0000-0000-636fd323bda7","type":"received","side":"sell","product_id":"BTC-USD","time":"2022-09-26T04:01:05.113783Z","sequence":46725053025},{"price":"18866.1","order_id":"6c2bc33c-2638-4846-bade-a4fc0c44ea3b","remaining_size":"0.00501734","type":"open","side":"sell","product_id":"BTC-USD","time":"2022-09-26T04:01:05.113783Z","sequence":46725053026},{"order_id":"10e1ac6a-4f4a-4372-b93e-be47d401a452","order_type":"limit","size":"0.02198","price":"18866.1","client_oid":"20220926-0000-0000-0005-000000220051","type":"received","side":"sell","product_id":"BTC-USD","time":"2022-09-26T04:01:05.118074Z","sequence":46725053027},{"price":"18866.1","order_id":"10e1ac6a-4f4a-4372-b93e-be47d401a452","remaining_size":"0.02198","type":"open","side":"sell","product_id":"BTC-USD","time":"2022-09-26T04:01:05.118074Z","sequence":46725053028},{"order_id":"10e1ac6a-4f4a-4372-b93e-be47d401a452","reason":"canceled","price":"18866.1","remaining_size":"0.02198","type":"done","side":"sell","product_id":"BTC-USD","time":"2022-09-26T04:01:05.122789Z","sequence":46725053029},{"order_id":"6c2bc33c-2638-4846-bade-a4fc0c44ea3b","reason":"canceled","price":"18866.1","remaining_size":"0.00501734","type":"done","side":"sell","product_id":"BTC-USD","time":"2022-09-26T04:01:05.129012Z","sequence":46725053030},{"order_id":"8e5cfb46-f98b-46e0-aa70-5da7742e118c","order_type":"limit","size":"0.00503507","price":"18866.1","client_oid":"65122000-0000-0000-0000-636fd32400cb","type":"received","side":"sell","product_id":"BTC-USD","time":"2022-09-26T04:01:05.130185Z","sequence":46725053031},{"price":"18866.1","order_id":"8e5cfb46-f98b-46e0-aa70-5da7742e118c","remaining_size":"0.00503507","type":"open","side":"sell","product_id":"BTC-USD","time":"2022-09-26T04:01:05.130185Z","sequence":46725053032},{"order_id":"49272ee9-eefa-40ea-b6b3-47dab08b35b2","order_type":"limit","size":"0.02198","price":"18866.1","client_oid":"20220926-0000-0000-0001-000000213681","type":"received","side":"sell","product_id":"BTC-USD","time":"2022-09-26T04:01:05.140893Z","sequence":46725053033},{"price":"18866.1","order_id":"49272ee9-eefa-40ea-b6b3-47dab08b35b2","remaining_size":"0.02198","type":"open","side":"sell","product_id":"BTC-USD","time":"2022-09-26T04:01:05.140893Z","sequence":46725053034},{"order_id":"ae36aa6f-7e75-4748-a6e3-e1f98ced0bc1","reason":"canceled","price":"18863.8","remaining_size":"0.01972661","type":"done","side":"buy","product_id":"BTC-USD","time":"2022-09-26T04:01:05.147249Z","sequence":46725053035},{"order_id":"66b87829-fbfc-436f-ad20-1c929358e39a","order_type":"limit","size":"0.00501734","price":"18866.1","client_oid":"75122000-0000-0000-0000-636fd323bda7","type":"received","side":"sell","product_id":"BTC-USD","time":"2022-09-26T04:01:05.153767Z","sequence":46725053036},{"price":"18866.1","order_id":"66b87829-fbfc-436f-ad20-1c929358e39a","remaining_size":"0.00501734","type":"open","side":"sell","product_id":"BTC-USD","time":"2022-09-26T04:01:05.153767Z","sequence":46725053037},{"order_id":"9955ff37-16cb-445b-a626-a8ef254e5e4f","order_type":"limit","size":"0.01972661","price":"18863.03","client_oid":"00000000-0000-0000-0005-e958faed5473","type":"received","side":"buy","product_id":"BTC-USD","time":"2022-09-26T04:01:05.154096Z","sequence":46725053038},{"price":"18863.03","order_id":"9955ff37-16cb-445b-a626-a8ef254e5e4f","remaining_size":"0.01972661","type":"open","side":"buy","product_id":"BTC-USD","time":"2022-09-26T04:01:05.154096Z","sequence":46725053039},{"order_id":"4703c748-9e9f-4e77-9bed-3618c72a84ac","order_type":"limit","size":"0.01612182","price":"18866.1","client_oid":"75122000-0000-0000-0000-636fd323eee7","type":"received","side":"sell","product_id":"BTC-USD","time":"2022-09-26T04:01:05.206658Z","sequence":46725053040},{"price":"18866.1","order_id":"4703c748-9e9f-4e77-9bed-3618c72a84ac","remaining_size":"0.01612182","type":"open","side":"sell","product_id":"BTC-USD","time":"2022-09-26T04:01:05.206658Z","sequence":46725053041},{"order_id":"8e5cfb46-f98b-46e0-aa70-5da7742e118c","reason":"canceled","price":"18866.1","remaining_size":"0.00503507","type":"done","side":"sell","product_id":"BTC-USD","time":"2022-09-26T04:01:05.207052Z","sequence":46725053042},{"order_id":"66b87829-fbfc-436f-ad20-1c929358e39a","reason":"canceled","price":"18866.1","remaining_size":"0.00501734","type":"done","side":"sell","product_id":"BTC-USD","time":"2022-09-26T04:01:05.208026Z","sequence":46725053043},{"order_id":"6f051cc4-58f0-4afa-bdc1-1c3f6fff44c7","reason":"canceled","price":"19375.29","remaining_size":"0.0010706","type":"done","side":"sell","product_id":"BTC-USD","time":"2022-09-26T04:01:05.211962Z","sequence":46725053044},{"order_id":"49272ee9-eefa-40ea-b6b3-47dab08b35b2","reason":"canceled","price":"18866.1","remaining_size":"0.02198","type":"done","side":"sell","product_id":"BTC-USD","time":"2022-09-26T04:01:05.212570Z","sequence":46725053045},{"order_id":"4703c748-9e9f-4e77-9bed-3618c72a84ac","reason":"canceled","price":"18866.1","remaining_size":"0.01612182","type":"done","side":"sell","product_id":"BTC-USD","time":"2022-09-26T04:01:05.212880Z","sequence":46725053046},{"order_id":"9955ff37-16cb-445b-a626-a8ef254e5e4f","reason":"canceled","price":"18863.03","remaining_size":"0.01972661","type":"done","side":"buy","product_id":"BTC-USD","time":"2022-09-26T04:01:05.219039Z","sequence":46725053047},{"order_id":"6b89aa78-90c3-4125-baac-31cbf13b95d8","order_type":"limit","size":"0.01972661","price":"18863.56","client_oid":"00000000-0000-0000-0005-e958faed5482","type":"received","side":"buy","product_id":"BTC-USD","time":"2022-09-26T04:01:05.224255Z","sequence":46725053048},{"price":"18863.56","order_id":"6b89aa78-90c3-4125-baac-31cbf13b95d8","remaining_size":"0.01972661","type":"open","side":"buy","product_id":"BTC-USD","time":"2022-09-26T04:01:05.224255Z","sequence":46725053049},{"order_id":"82944896-c7d1-4f38-ac29-b5ad69a36999","order_type":"limit","size":"0.0010706","price":"19375.18","client_oid":"00000000-0000-0000-0005-e958faed5481","type":"received","side":"sell","product_id":"BTC-USD","time":"2022-09-26T04:01:05.224340Z","sequence":46725053050},{"price":"19375.18","order_id":"82944896-c7d1-4f38-ac29-b5ad69a36999","remaining_size":"0.0010706","type":"open","side":"sell","product_id":"BTC-USD","time":"2022-09-26T04:01:05.224340Z","sequence":46725053051},{"order_id":"6b89aa78-90c3-4125-baac-31cbf13b95d8","reason":"canceled","price":"18863.56","remaining_size":"0.01972661","type":"done","side":"buy","product_id":"BTC-USD","time":"2022-09-26T04:01:05.230590Z","sequence":46725053052},{"order_id":"35d22def-a05f-4864-8c0f-cf2cdbc7d32f","order_type":"limit","size":"0.01972661","price":"18863.63","client_oid":"00000000-0000-0000-0005-e958faed5486","type":"received","side":"buy","product_id":"BTC-USD","time":"2022-09-26T04:01:05.236898Z","sequence":46725053053},{"price":"18863.63","order_id":"35d22def-a05f-4864-8c0f-cf2cdbc7d32f","remaining_size":"0.01972661","type":"open","side":"buy","product_id":"BTC-USD","time":"2022-09-26T04:01:05.236898Z","sequence":46725053054},{"order_id":"35d22def-a05f-4864-8c0f-cf2cdbc7d32f","reason":"canceled","price":"18863.63","remaining_size":"0.01972661","type":"done","side":"buy","product_id":"BTC-USD","time":"2022-09-26T04:01:05.239914Z","sequence":46725053055},{"order_id":"708f78fd-77ea-49ec-8aca-a24a44b5f919","order_type":"limit","size":"0.01972661","price":"18863.64","client_oid":"00000000-0000-0000-0005-e958faed5487","type":"received","side":"buy","product_id":"BTC-USD","time":"2022-09-26T04:01:05.242039Z","sequence":46725053056},{"price":"18863.64","order_id":"708f78fd-77ea-49ec-8aca-a24a44b5f919","remaining_size":"0.01972661","type":"open","side":"buy","product_id":"BTC-USD","time":"2022-09-26T04:01:05.242039Z","sequence":46725053057},{"order_id":"399e5637-2a78-4472-a3b2-70fd19817ce9","order_type":"limit","size":"0.02545024","price":"18866.1","client_oid":"85122000-0000-0000-0000-636fd323e260","type":"received","side":"sell","product_id":"BTC-USD","time":"2022-09-26T04:01:05.247485Z","sequence":46725053058},{"price":"18866.1","order_id":"399e5637-2a78-4472-a3b2-70fd19817ce9","remaining_size":"0.02545024","type":"open","side":"sell","product_id":"BTC-USD","time":"2022-09-26T04:01:05.247485Z","sequence":46725053059},{"order_id":"401f1b6b-7683-4f97-b4b5-c7a595c5fbf2","order_type":"limit","size":"0.02198","price":"18866.1","client_oid":"20220926-0000-0000-0004-000000217189","type":"received","side":"sell","product_id":"BTC-USD","time":"2022-09-26T04:01:05.262456Z","sequence":46725053060},{"price":"18866.1","order_id":"401f1b6b-7683-4f97-b4b5-c7a595c5fbf2","remaining_size":"0.02198","type":"open","side":"sell","product_id":"BTC-USD","time":"2022-09-26T04:01:05.262456Z","sequence":46725053061},{"type":"heartbeat","last_trade_id":418306576,"product_id":"BTC-USD","sequence":46725053061,"time":"2022-09-26T04:01:05.414269Z"},{"order_id":"0d6c37ad-253d-4321-9c53-c69bdd6f6a1e","reason":"canceled","price":"18864.15","remaining_size":"0.04397419","type":"done","side":"buy","product_id":"BTC-USD","time":"2022-09-26T04:01:05.451188Z","sequence":46725053062},{"order_id":"0ca7f5f8-d3f7-4af0-9046-d9cce53463e9","order_type":"limit","size":"0.00073829","price":"19247.17","client_oid":"a3340cc3-6163-42a5-872e-ce0e6cc8e09c","type":"received","side":"buy","product_id":"BTC-USD","time":"2022-09-26T04:01:05.498695Z","sequence":46725053063},{"trade_id":418306577,"maker_order_id":"5d198d02-6c59-44a0-a4c0-770bc8780beb","taker_order_id":"0ca7f5f8-d3f7-4af0-9046-d9cce53463e9","size":"0.00073829","price":"18866.1","type":"match","side":"sell","product_id":"BTC-USD","time":"2022-09-26T04:01:05.498695Z","sequence":46725053064},{"order_id":"0ca7f5f8-d3f7-4af0-9046-d9cce53463e9","reason":"filled","price":"19247.17","remaining_size":"0","type":"done","side":"buy","product_id":"BTC-USD","time":"2022-09-26T04:01:05.498695Z","sequence":46725053065},{"order_id":"401f1b6b-7683-4f97-b4b5-c7a595c5fbf2","reason":"canceled","price":"18866.1","remaining_size":"0.02198","type":"done","side":"sell","product_id":"BTC-USD","time":"2022-09-26T04:01:05.505129Z","sequence":46725053066},{"order_id":"399e5637-2a78-4472-a3b2-70fd19817ce9","reason":"canceled","price":"18866.1","remaining_size":"0.02545024","type":"done","side":"sell","product_id":"BTC-USD","time":"2022-09-26T04:01:05.506619Z","sequence":46725053067},{"order_id":"7f1f6cb2-3e80-4f74-92a1-d0f783f42629","order_type":"limit","size":"0.00153006","price":"18866.1","client_oid":"2b86300e-f17d-43a8-95e4-51cebbc5f9c8","type":"received","side":"sell","product_id":"BTC-USD","time":"2022-09-26T04:01:05.509781Z","sequence":46725053068},{"price":"18866.1","order_id":"7f1f6cb2-3e80-4f74-92a1-d0f783f42629","remaining_size":"0.00153006","type":"open","side":"sell","product_id":"BTC-USD","time":"2022-09-26T04:01:05.509781Z","sequence":46725053069},{"order_id":"708f78fd-77ea-49ec-8aca-a24a44b5f919","reason":"canceled","price":"18863.64","remaining_size":"0.01972661","type":"done","side":"buy","product_id":"BTC-USD","time":"2022-09-26T04:01:05.513039Z","sequence":46725053070},{"order_id":"5fb1506f-7236-4fc9-93e0-8aa3753e1742","order_type":"limit","size":"0.02097098","price":"18863.69","client_oid":"00000000-0000-0000-0005-e958faed549c","type":"received","side":"buy","product_id":"BTC-USD","time":"2022-09-26T04:01:05.518162Z","sequence":46725053071},{"price":"18863.69","order_id":"5fb1506f-7236-4fc9-93e0-8aa3753e1742","remaining_size":"0.02097098","type":"open","side":"buy","product_id":"BTC-USD","time":"2022-09-26T04:01:05.518162Z","sequence":46725053072},{"order_id":"1887ce86-1ef7-4478-89b4-b7ee06cb8aa8","order_type":"limit","size":"0.01213881","price":"18866.1","client_oid":"95122000-0000-0000-0000-636fd323e260","type":"received","side":"sell","product_id":"BTC-USD","time":"2022-09-26T04:01:05.518497Z","sequence":46725053073},{"price":"18866.1","order_id":"1887ce86-1ef7-4478-89b4-b7ee06cb8aa8","remaining_size":"0.01213881","type":"open","side":"sell","product_id":"BTC-USD","time":"2022-09-26T04:01:05.518497Z","sequence":46725053074},{"order_id":"68502428-5bff-4336-a413-7491e1fbc717","order_type":"limit","size":"0.02198","price":"18866.1","client_oid":"20220926-0000-0000-0005-000000220054","type":"received","side":"sell","product_id":"BTC-USD","time":"2022-09-26T04:01:05.522713Z","sequence":46725053075},{"price":"18866.1","order_id":"68502428-5bff-4336-a413-7491e1fbc717","remaining_size":"0.02198","type":"open","side":"sell","product_id":"BTC-USD","time":"2022-09-26T04:01:05.522713Z","sequence":46725053076},{"order_id":"c9085fc1-9764-42b0-9336-28a901b495f3","reason":"canceled","price":"18866.09","remaining_size":"0.015","type":"done","side":"buy","product_id":"BTC-USD","time":"2022-09-26T04:01:05.528105Z","sequence":46725053077},{"order_id":"1887ce86-1ef7-4478-89b4-b7ee06cb8aa8","reason":"canceled","price":"18866.1","remaining_size":"0.01213881","type":"done","side":"sell","product_id":"BTC-USD","time":"2022-09-26T04:01:05.535573Z","sequence":46725053078},{"order_id":"8b088d94-f5f8-438e-89ea-05fef02a3980","order_type":"limit","size":"0.00560839","price":"18866.1","client_oid":"06122000-0000-0000-0000-636fd323bda7","type":"received","side":"sell","product_id":"BTC-USD","time":"2022-09-26T04:01:05.536033Z","sequence":46725053079},{"price":"18866.1","order_id":"8b088d94-f5f8-438e-89ea-05fef02a3980","remaining_size":"0.00560839","type":"open","side":"sell","product_id":"BTC-USD","time":"2022-09-26T04:01:05.536033Z","sequence":46725053080},{"order_id":"4f6a9bce-2c68-4624-950b-e524e4e09f5a","order_type":"limit","size":"0.015","price":"18866.09","client_oid":"9810e463-f495-40a4-ae69-30fa5be0e826","type":"received","side":"buy","product_id":"BTC-USD","time":"2022-09-26T04:01:05.536285Z","sequence":46725053081},{"price":"18866.09","order_id":"4f6a9bce-2c68-4624-950b-e524e4e09f5a","remaining_size":"0.015","type":"open","side":"buy","product_id":"BTC-USD","time":"2022-09-26T04:01:05.536285Z","sequence":46725053082},{"order_id":"b509d1a4-796b-452c-a978-4d2dc71b0e54","reason":"canceled","price":"18866.96","remaining_size":"0.05","type":"done","side":"sell","product_id":"BTC-USD","time":"2022-09-26T04:01:05.541924Z","sequence":46725053083},{"order_id":"68502428-5bff-4336-a413-7491e1fbc717","reason":"canceled","price":"18866.1","remaining_size":"0.02198","type":"done","side":"sell","product_id":"BTC-USD","time":"2022-09-26T04:01:05.542357Z","sequence":46725053084},{"order_id":"4f6a9bce-2c68-4624-950b-e524e4e09f5a","reason":"canceled","price":"18866.09","remaining_size":"0.015","type":"done","side":"buy","product_id":"BTC-USD","time":"2022-09-26T04:01:05.547471Z","sequence":46725053085},{"order_id":"83b49307-f275-47d6-b6aa-77a45c5c2c81","order_type":"limit","size":"0.05","price":"18866.1","client_oid":"5d713e7c-1238-1807-37cd-23ca204d1817","type":"received","side":"sell","product_id":"BTC-USD","time":"2022-09-26T04:01:05.549099Z","sequence":46725053086},{"price":"18866.1","order_id":"83b49307-f275-47d6-b6aa-77a45c5c2c81","remaining_size":"0.05","type":"open","side":"sell","product_id":"BTC-USD","time":"2022-09-26T04:01:05.549099Z","sequence":46725053087},{"order_id":"86239948-248b-45b3-b965-f0a597693e56","order_type":"limit","size":"0.0187088","price":"18866.1","client_oid":"16122000-0000-0000-0000-636fd323bda7","type":"received","side":"sell","product_id":"BTC-USD","time":"2022-09-26T04:01:05.549502Z","sequence":46725053088},{"price":"18866.1","order_id":"86239948-248b-45b3-b965-f0a597693e56","remaining_size":"0.0187088","type":"open","side":"sell","product_id":"BTC-USD","time":"2022-09-26T04:01:05.549502Z","sequence":46725053089},{"order_id":"8b088d94-f5f8-438e-89ea-05fef02a3980","reason":"canceled","price":"18866.1","remaining_size":"0.00560839","type":"done","side":"sell","product_id":"BTC-USD","time":"2022-09-26T04:01:05.553187Z","sequence":46725053090},{"order_id":"6da5d1af-467d-4299-99e3-04ef0beb323f","order_type":"limit","size":"0.015","price":"18866.09","client_oid":"516c031b-071c-42a1-9a74-c8d8feea261b","type":"received","side":"buy","product_id":"BTC-USD","time":"2022-09-26T04:01:05.555454Z","sequence":46725053091},{"price":"18866.09","order_id":"6da5d1af-467d-4299-99e3-04ef0beb323f","remaining_size":"0.015","type":"open","side":"buy","product_id":"BTC-USD","time":"2022-09-26T04:01:05.555454Z","sequence":46725053092},{"order_id":"86239948-248b-45b3-b965-f0a597693e56","reason":"canceled","price":"18866.1","remaining_size":"0.0187088","type":"done","side":"sell","product_id":"BTC-USD","time":"2022-09-26T04:01:05.556669Z","sequence":46725053093},{"order_id":"afa531cf-a1cc-4232-8ccc-c2feab2e8bb5","order_type":"limit","size":"0.01455406","price":"18865.41","client_oid":"16122000-0000-0000-0000-636fd323eee7","type":"received","side":"buy","product_id":"BTC-USD","time":"2022-09-26T04:01:05.560801Z","sequence":46725053094},{"price":"18865.41","order_id":"afa531cf-a1cc-4232-8ccc-c2feab2e8bb5","remaining_size":"0.01455406","type":"open","side":"buy","product_id":"BTC-USD","time":"2022-09-26T04:01:05.560801Z","sequence":46725053095},{"order_id":"9eec13f7-2420-46bd-aef3-e6817a63b2a3","order_type":"limit","size":"0.02198","price":"18866.1","client_oid":"20220926-0000-0000-0006-000000218243","type":"received","side":"sell","product_id":"BTC-USD","time":"2022-09-26T04:01:05.560813Z","sequence":46725053096},{"price":"18866.1","order_id":"9eec13f7-2420-46bd-aef3-e6817a63b2a3","remaining_size":"0.02198","type":"open","side":"sell","product_id":"BTC-USD","time":"2022-09-26T04:01:05.560813Z","sequence":46725053097},{"order_id":"6da5d1af-467d-4299-99e3-04ef0beb323f","reason":"canceled","price":"18866.09","remaining_size":"0.015","type":"done","side":"buy","product_id":"BTC-USD","time":"2022-09-26T04:01:05.562943Z","sequence":46725053098},{"order_id":"9eec13f7-2420-46bd-aef3-e6817a63b2a3","reason":"canceled","price":"18866.1","remaining_size":"0.02198","type":"done","side":"sell","product_id":"BTC-USD","time":"2022-09-26T04:01:05.565927Z","sequence":46725053099},{"order_id":"b0d7b74b-ce16-4677-a55a-4dc8552703fa","order_type":"limit","size":"0.00555769","price":"18866.1","client_oid":"26122000-0000-0000-0000-636fd32400cb","type":"received","side":"sell","product_id":"BTC-USD","time":"2022-09-26T04:01:05.568710Z","sequence":46725053100},{"price":"18866.1","order_id":"b0d7b74b-ce16-4677-a55a-4dc8552703fa","remaining_size":"0.00555769","type":"open","side":"sell","product_id":"BTC-USD","time":"2022-09-26T04:01:05.568710Z","sequence":46725053101},{"order_id":"afa531cf-a1cc-4232-8ccc-c2feab2e8bb5","reason":"canceled","price":"18865.41","remaining_size":"0.01455406","type":"done","side":"buy","product_id":"BTC-USD","time":"2022-09-26T04:01:05.569007Z","sequence":46725053102},{"order_id":"b77e84de-b813-43ce-933a-40108753ee08","order_type":"limit","size":"0.00828186","price":"18866.1","client_oid":"36122000-0000-0000-0000-636fd323bda7","type":"received","side":"sell","product_id":"BTC-USD","time":"2022-09-26T04:01:05.572844Z","sequence":46725053103},{"price":"18866.1","order_id":"b77e84de-b813-43ce-933a-40108753ee08","remaining_size":"0.00828186","type":"open","side":"sell","product_id":"BTC-USD","time":"2022-09-26T04:01:05.572844Z","sequence":46725053104},{"order_id":"876ef71c-e582-45f6-a9fc-184dfa89b7e5","order_type":"limit","size":"0.01197769","price":"18866.1","client_oid":"36122000-0000-0000-0000-636fd323e260","type":"received","side":"sell","product_id":"BTC-USD","time":"2022-09-26T04:01:05.572998Z","sequence":46725053105},{"price":"18866.1","order_id":"876ef71c-e582-45f6-a9fc-184dfa89b7e5","remaining_size":"0.01197769","type":"open","side":"sell","product_id":"BTC-USD","time":"2022-09-26T04:01:05.572998Z","sequence":46725053106},{"order_id":"b0d7b74b-ce16-4677-a55a-4dc8552703fa","reason":"canceled","price":"18866.1","remaining_size":"0.00555769","type":"done","side":"sell","product_id":"BTC-USD","time":"2022-09-26T04:01:05.574637Z","sequence":46725053107},{"order_id":"bb3ba635-a879-4498-891e-e5fed30d1906","reason":"canceled","price":"18866.1","remaining_size":"0.02198","type":"done","side":"sell","product_id":"BTC-USD","time":"2022-09-26T04:01:05.584265Z","sequence":46725053112},{"order_id":"4b0062a7-64c3-4502-baed-e6041407c338","order_type":"limit","size":"0.00914827","price":"18865.41","client_oid":"36122000-0000-0000-0000-636fd32400cb","type":"received","side":"buy","product_id":"BTC-USD","time":"2022-09-26T04:01:05.584730Z","sequence":46725053113}]