[{"type":"subscriptions","channels":[{"name":"heartbeat","product_ids":["BTC-USD"]},{"name":"full","product_ids":["BTC-USD"]}]},{"order_id":"806e0824-b000-428b-aec9-1d9a29cd1e67","reason":"canceled","price":"18856.39","remaining_size":"0.02265507","type":"done","side":"buy","product_id":"BTC-USD","time":"2022-09-26T03:54:17.402687Z","sequence":46724808575},{"order_id":"3e1da15f-fe47-4432-9110-2dcc3b976db9","reason":"canceled","price":"18862.79","remaining_size":"0.01504935","type":"done","side":"sell","product_id":"BTC-USD","time":"2022-09-26T03:54:17.408441Z","sequence":46724808576},{"order_id":"9fb433ae-cabd-4ae0-a507-fc88e31bcfa7","order_type":"limit","size":"0.01305696","price":"18856.38","client_oid":"b72972d9-4917-ccc2-7c94-fbf8ce80fb43","type":"received","side":"buy","product_id":"BTC-USD","time":"2022-09-26T03:54:17.408755Z","sequence":46724808577},{"price":"18856.38","order_id":"9fb433ae-cabd-4ae0-a507-fc88e31bcfa7","remaining_size":"0.01305696","type":"open","side":"buy","product_id":"BTC-USD","time":"2022-09-26T03:54:17.408755Z","sequence":46724808578},{"type":"heartbeat","last_trade_id":418304777,"product_id":"BTC-USD","sequence":46724808578,"time":"2022-09-26T03:54:17.413486Z"},{"order_id":"c014c513-d650-42ca-b74a-e93ac6d41a39","order_type":"limit","size":"0.02203617","price":"18856.77","client_oid":"69ee229b-7060-4a6d-16bc-d33c34705869","type":"received","side":"buy","product_id":"BTC-USD","time":"2022-09-26T03:54:17.456806Z","sequence":46724808579},{"price":"18856.77","order_id":"c014c513-d650-42ca-b74a-e93ac6d41a39","remaining_size":"0.02203617","type":"open","side":"buy","product_id":"BTC-USD","time":"2022-09-26T03:54:17.456806Z","sequence":46724808580},{"order_id":"e373cae8-bda1-4398-aea9-693f676c1e10","order_type":"limit","size":"0.01504935","price":"18862.79","client_oid":"e4da22e5-3d4e-11ed-8a20-0aa09ad95c5f","type":"received","side":"sell","product_id":"BTC-USD","time":"2022-09-26T03:54:17.468002Z","sequence":46724808581},{"price":"18862.79","order_id":"e373cae8-bda1-4398-aea9-693f676c1e10","remaining_size":"0.01504935","type":"open","side":"sell","product_id":"BTC-USD","time":"2022-09-26T03:54:17.468002Z","sequence":46724808582},{"order_id":"82f8e127-10aa-40a2-b682-7b908d268ee9","order_type":"market","funds":"24.5101709706","client_oid":"c3240899-e7e9-42f7-9ca9-964accf15169","type":"received","side":"buy","product_id":"BTC-USD","time":"2022-09-26T03:54:17.468377Z","sequence":46724808583},{"trade_id":418304778,"maker_order_id":"7240be68-38ec-43d0-bbe1-73d0deac1d70","taker_order_id":"82f8e127-10aa-40a2-b682-7b908d268ee9","size":"0.00129966","price":"18858.91","type":"match","side":"sell","product_id":"BTC-USD","time":"2022-09-26T03:54:17.468377Z","sequence":46724808584},{"order_id":"82f8e127-10aa-40a2-b682-7b908d268ee9","reason":"filled","remaining_size":"0","type":"done","side":"buy","product_id":"BTC-USD","time":"2022-09-26T03:54:17.468377Z","sequence":46724808585},{"order_id":"ab124773-6d30-485e-8ecf-836c7c9506dd","reason":"canceled","price":"18856.32","remaining_size":"0.02575327","type":"done","side":"buy","product_id":"BTC-USD","time":"2022-09-26T03:54:17.473722Z","sequence":46724808586},{"order_id":"2c69d416-626c-40f3-9b86-b0938f6225ca","order_type":"limit","size":"0.00123467","price":"18858.91","client_oid":"a8fce11b-e0c9-42c5-b40b-70f264ea285a","type":"received","side":"sell","product_id":"BTC-USD","time":"2022-09-26T03:54:17.480293Z","sequence":46724808587},{"price":"18858.91","order_id":"2c69d416-626c-40f3-9b86-b0938f6225ca","remaining_size":"0.00123467","type":"open","side":"sell","product_id":"BTC-USD","time":"2022-09-26T03:54:17.480293Z","sequence":46724808588},{"order_id":"511e85e0-3df2-411c-ad6b-20835bef7c10","order_type":"limit","size":"0.02417","price":"18858.9","client_oid":"20220926-0000-0000-0005-000000216027","type":"received","side":"buy","product_id":"BTC-USD","time":"2022-09-26T03:54:17.480310Z","sequence":46724808589},{"price":"18858.9","order_id":"511e85e0-3df2-411c-ad6b-20835bef7c10","remaining_size":"0.02417","type":"open","side":"buy","product_id":"BTC-USD","time":"2022-09-26T03:54:17.480310Z","sequence":46724808590},{"order_id":"67d78dfc-7f7a-4ec3-b45a-5e0b20a5356d","order_type":"limit","size":"0.02575327","price":"18856.39","client_oid":"00000000-0000-0000-0005-e958faec78c4","type":"received","side":"buy","product_id":"BTC-USD","time":"2022-09-26T03:54:17.480640Z","sequence":46724808591},{"price":"18856.39","order_id":"67d78dfc-7f7a-4ec3-b45a-5e0b20a5356d","remaining_size":"0.02575327","type":"open","side":"buy","product_id":"BTC-USD","time":"2022-09-26T03:54:17.480640Z","sequence":46724808592},{"order_id":"511e85e0-3df2-411c-ad6b-20835bef7c10","reason":"canceled","price":"18858.9","remaining_size":"0.02417","type":"done","side":"buy","product_id":"BTC-USD","time":"2022-09-26T03:54:17.486352Z","sequence":46724808593},{"order_id":"b3fdf3d9-5955-4229-ab08-613d56e3b2da","reason":"canceled","price":"18857.73","remaining_size":"0.01492711","type":"done","side":"buy","product_id":"BTC-USD","time":"2022-09-26T03:54:17.487827Z","sequence":46724808594},{"order_id":"67d78dfc-7f7a-4ec3-b45a-5e0b20a5356d","reason":"canceled","price":"18856.39","remaining_size":"0.02575327","type":"done","side":"buy","product_id":"BTC-USD","time":"2022-09-26T03:54:17.488070Z","sequence":46724808595},{"order_id":"508f0dde-dfe7-4531-a948-f623484a25cd","reason":"canceled","price":"18857.76","remaining_size":"0.01388968","type":"done","side":"buy","product_id":"BTC-USD","time":"2022-09-26T03:54:17.488081Z","sequence":46724808596},{"order_id":"e8996a1d-7574-4edb-a05b-2eba18169cff","reason":"canceled","price":"18857.73","remaining_size":"0.0076835","type":"done","side":"buy","product_id":"BTC-USD","time":"2022-09-26T03:54:17.488121Z","sequence":46724808597},{"order_id":"33dc8852-46b3-4ab5-b2d8-e59757b8656a","reason":"canceled","price":"18857.73","remaining_size":"0.00849971","type":"done","side":"buy","product_id":"BTC-USD","time":"2022-09-26T03:54:17.490863Z","sequence":46724808598},{"order_id":"e373cae8-bda1-4398-aea9-693f676c1e10","reason":"canceled","price":"18862.79","remaining_size":"0.01504935","type":"done","side":"sell","product_id":"BTC-USD","time":"2022-09-26T03:54:17.493246Z","sequence":46724808599},{"order_id":"cadab0e5-42a9-439e-b161-1480eaaffbd4","order_type":"limit","size":"0.02575327","price":"18856.59","client_oid":"00000000-0000-0000-0005-e958faec78c6","type":"received","side":"buy","product_id":"BTC-USD","time":"2022-09-26T03:54:17.494104Z","sequence":46724808600},{"price":"18856.59","order_id":"cadab0e5-42a9-439e-b161-1480eaaffbd4","remaining_size":"0.02575327","type":"open","side":"buy","product_id":"BTC-USD","time":"2022-09-26T03:54:17.494104Z","sequence":46724808601},{"order_id":"e929b9d7-c817-49b1-81e6-052d2ae1784f","order_type":"limit","size":"0.045","price":"18858.9","client_oid":"57641000-0000-0000-0000-636fd32400cb","type":"received","side":"buy","product_id":"BTC-USD","time":"2022-09-26T03:54:17.497532Z","sequence":46724808602},{"price":"18858.9","order_id":"e929b9d7-c817-49b1-81e6-052d2ae1784f","remaining_size":"0.045","type":"open","side":"buy","product_id":"BTC-USD","time":"2022-09-26T03:54:17.497532Z","sequence":46724808603},{"order_id":"3090e284-45cf-45c0-8727-212c40739911","order_type":"market","funds":"0.0099952223","client_oid":"68a3a1b5-6c01-4350-b7a8-6e392d42dd01","type":"received","side":"buy","product_id":"BTC-USD","time":"2022-09-26T03:54:17.501135Z","sequence":46724808604},{"trade_id":418304779,"maker_order_id":"7240be68-38ec-43d0-bbe1-73d0deac1d70","taker_order_id":"3090e284-45cf-45c0-8727-212c40739911","size":"0.00000053","price":"18858.91","type":"match","side":"sell","product_id":"BTC-USD","time":"2022-09-26T03:54:17.501135Z","sequence":46724808605},{"order_id":"3090e284-45cf-45c0-8727-212c40739911","reason":"filled","remaining_size":"0","type":"done","side":"buy","product_id":"BTC-USD","time":"2022-09-26T03:54:17.501135Z","sequence":46724808606},{"order_id":"e929b9d7-c817-49b1-81e6-052d2ae1784f","reason":"canceled","price":"18858.9","remaining_size":"0.045","type":"done","side":"buy","product_id":"BTC-USD","time":"2022-09-26T03:54:17.503528Z","sequence":46724808607},{"order_id":"e602a0ef-2d5f-4be7-b8e9-2725f2e6dfe4","order_type":"limit","size":"0.05","price":"18857.71","client_oid":"e4df6ea2-3d4e-11ed-bb3d-0a8f16458089","type":"received","side":"buy","product_id":"BTC-USD","time":"2022-09-26T03:54:17.505151Z","sequence":46724808608},{"price":"18857.71","order_id":"e602a0ef-2d5f-4be7-b8e9-2725f2e6dfe4","remaining_size":"0.05","type":"open","side":"buy","product_id":"BTC-USD","time":"2022-09-26T03:54:17.505151Z","sequence":46724808609},{"order_id":"3dd0d15d-113e-44c0-b653-84bab065631a","order_type":"limit","size":"0.045","price":"18857.73","client_oid":"67641000-0000-0000-0000-636fd323e260","type":"received","side":"buy","product_id":"BTC-USD","time":"2022-09-26T03:54:17.508491Z","sequence":46724808610},{"price":"18857.73","order_id":"3dd0d15d-113e-44c0-b653-84bab065631a","remaining_size":"0.045","type":"open","side":"buy","product_id":"BTC-USD","time":"2022-09-26T03:54:17.508491Z","sequence":46724808611},{"order_id":"23662317-86cb-44fe-8e7e-70f13f9d7395","order_type":"limit","size":"0.01504935","price":"18862.79","client_oid":"e4e05b60-3d4e-11ed-8a20-0aa09ad95c5f","type":"received","side":"sell","product_id":"BTC-USD","time":"2022-09-26T03:54:17.508530Z","sequence":46724808612},{"price":"18862.79","order_id":"23662317-86cb-44fe-8e7e-70f13f9d7395","remaining_size":"0.01504935","type":"open","side":"sell","product_id":"BTC-USD","time":"2022-09-26T03:54:17.508530Z","sequence":46724808613},{"order_id":"db7811b6-e91b-4e52-a236-90142ecb4239","order_type":"limit","size":"0.02417","price":"18858.9","client_oid":"20220926-0000-0000-0006-000000214253","type":"received","side":"buy","product_id":"BTC-USD","time":"2022-09-26T03:54:17.508837Z","sequence":46724808614},{"price":"18858.9","order_id":"db7811b6-e91b-4e52-a236-90142ecb4239","remaining_size":"0.02417","type":"open","side":"buy","product_id":"BTC-USD","time":"2022-09-26T03:54:17.508837Z","sequence":46724808615},{"order_id":"db7811b6-e91b-4e52-a236-90142ecb4239","reason":"canceled","price":"18858.9","remaining_size":"0.02417","type":"done","side":"buy","product_id":"BTC-USD","time":"2022-09-26T03:54:17.513403Z","sequence":46724808616},{"order_id":"cadab0e5-42a9-439e-b161-1480eaaffbd4","reason":"canceled","price":"18856.59","remaining_size":"0.02575327","type":"done","side":"buy","product_id":"BTC-USD","time":"2022-09-26T03:54:17.514440Z","sequence":46724808617},{"order_id":"3dd0d15d-113e-44c0-b653-84bab065631a","reason":"canceled","price":"18857.73","remaining_size":"0.045","type":"done","side":"buy","product_id":"BTC-USD","time":"2022-09-26T03:54:17.516571Z","sequence":46724808618},{"order_id":"0e1f0e91-3afb-4f50-8657-a208ac3dd892","order_type":"limit","size":"0.1","price":"18856.56","client_oid":"e4e17e97-3d4e-11ed-8b5d-abb0b41c20d0","type":"received","side":"buy","product_id":"BTC-USD","time":"2022-09-26T03:54:17.516590Z","sequence":46724808619},{"price":"18856.56","order_id":"0e1f0e91-3afb-4f50-8657-a208ac3dd892","remaining_size":"0.1","type":"open","side":"buy","product_id":"BTC-USD","time":"2022-09-26T03:54:17.516590Z","sequence":46724808620},{"order_id":"51c45760-290b-476d-9810-d734baeeccde","order_type":"limit","size":"0.01955329","price":"18856.78","client_oid":"a163f219-a707-47d5-b583-362df12a3f2d","type":"received","side":"buy","product_id":"BTC-USD","time":"2022-09-26T03:54:17.516985Z","sequence":46724808621},{"price":"18856.78","order_id":"51c45760-290b-476d-9810-d734baeeccde","remaining_size":"0.01955329","type":"open","side":"buy","product_id":"BTC-USD","time":"2022-09-26T03:54:17.516985Z","sequence":46724808622},{"order_id":"1a163853-8559-4a72-b851-b27e7324018c","reason":"canceled","price":"18856.55","remaining_size":"0.1","type":"done","side":"buy","product_id":"BTC-USD","time":"2022-09-26T03:54:17.519944Z","sequence":46724808623},{"order_id":"193c9916-e23c-41de-925e-722638a58e3d","order_type":"limit","size":"0.02534887","price":"18856.6","client_oid":"00000000-0000-0000-0005-e958faec78c7","type":"received","side":"buy","product_id":"BTC-USD","time":"2022-09-26T03:54:17.520491Z","sequence":46724808624},{"price":"18856.6","order_id":"193c9916-e23c-41de-925e-722638a58e3d","remaining_size":"0.02534887","type":"open","side":"buy","product_id":"BTC-USD","time":"2022-09-26T03:54:17.520491Z","sequence":46724808625},{"order_id":"782d92eb-42ee-4a50-b6fa-1b2b155144b5","order_type":"limit","size":"0.045","price":"18858.9","client_oid":"67641000-0000-0000-0000-636fd32400cb","type":"received","side":"buy","product_id":"BTC-USD","time":"2022-09-26T03:54:17.520650Z","sequence":46724808626},{"price":"18858.9","order_id":"782d92eb-42ee-4a50-b6fa-1b2b155144b5","remaining_size":"0.045","type":"open","side":"buy","product_id":"BTC-USD","time":"2022-09-26T03:54:17.520650Z","sequence":46724808627},{"order_id":"782d92eb-42ee-4a50-b6fa-1b2b155144b5","reason":"canceled","price":"18858.9","remaining_size":"0.045","type":"done","side":"buy","product_id":"BTC-USD","time":"2022-09-26T03:54:17.527133Z","sequence":46724808628},{"order_id":"23662317-86cb-44fe-8e7e-70f13f9d7395","reason":"canceled","price":"18862.79","remaining_size":"0.01504935","type":"done","side":"sell","product_id":"BTC-USD","time":"2022-09-26T03:54:17.533629Z","sequence":46724808629},{"order_id":"54f117e2-7321-4a59-bd9c-6792eb292a65","order_type":"limit","size":"0.02417","price":"18858.9","client_oid":"20220926-0000-0000-0001-000000209805","type":"received","side":"buy","product_id":"BTC-USD","time":"2022-09-26T03:54:17.534056Z","sequence":46724808630},{"price":"18858.9","order_id":"54f117e2-7321-4a59-bd9c-6792eb292a65","remaining_size":"0.02417","type":"open","side":"buy","product_id":"BTC-USD","time":"2022-09-26T03:54:17.534056Z","sequence":46724808631},{"order_id":"df58119e-7707-4d36-bccc-0276bef1fd46","order_type":"limit","size":"0.045","price":"18857.74","client_oid":"77641000-0000-0000-0000-636fd323bda7","type":"received","side":"buy","product_id":"BTC-USD","time":"2022-09-26T03:54:17.534255Z","sequence":46724808632},{"price":"18857.74","order_id":"df58119e-7707-4d36-bccc-0276bef1fd46","remaining_size":"0.045","type":"open","side":"buy","product_id":"BTC-USD","time":"2022-09-26T03:54:17.534255Z","sequence":46724808633},{"order_id":"54f117e2-7321-4a59-bd9c-6792eb292a65","reason":"canceled","price":"18858.9","remaining_size":"0.02417","type":"done","side":"buy","product_id":"BTC-USD","time":"2022-09-26T03:54:17.537964Z","sequence":46724808634},{"order_id":"95a22110-8aa8-4918-8bb5-2709edd9b38e","reason":"canceled","price":"18350.42","remaining_size":"0.0010709","type":"done","side":"buy","product_id":"BTC-USD","time":"2022-09-26T03:54:17.539266Z","sequence":46724808635},{"order_id":"df58119e-7707-4d36-bccc-0276bef1fd46","reason":"canceled","price":"18857.74","remaining_size":"0.045","type":"done","side":"buy","product_id":"BTC-USD","time":"2022-09-26T03:54:17.540297Z","sequence":46724808636},{"order_id":"bb94314a-4fb9-4e37-ab1a-41a87affafff","reason":"canceled","price":"19368.51","remaining_size":"0.00107099","type":"done","side":"sell","product_id":"BTC-USD","time":"2022-09-26T03:54:17.541016Z","sequence":46724808637},{"order_id":"438982cb-8def-4df5-ac84-dccba1380058","order_type":"limit","size":"0.045","price":"18858.9","client_oid":"77641000-0000-0000-0000-636fd323eee7","type":"received","side":"buy","product_id":"BTC-USD","time":"2022-09-26T03:54:17.546031Z","sequence":46724808638},{"price":"18858.9","order_id":"438982cb-8def-4df5-ac84-dccba1380058","remaining_size":"0.045","type":"open","side":"buy","product_id":"BTC-USD","time":"2022-09-26T03:54:17.546031Z","sequence":46724808639},{"order_id":"c426381c-9311-4763-94bf-063ea7b833c9","order_type":"limit","size":"0.00107099","price":"18349.62","client_oid":"00000000-0000-0000-0005-e958faec78c9","type":"received","side":"buy","product_id":"BTC-USD","time":"2022-09-26T03:54:17.549691Z","sequence":46724808640},{"price":"18349.62","order_id":"c426381c-9311-4763-94bf-063ea7b833c9","remaining_size":"0.00107099","type":"open","side":"buy","product_id":"BTC-USD","time":"2022-09-26T03:54:17.549691Z","sequence":46724808641},{"order_id":"438982cb-8def-4df5-ac84-dccba1380058","reason":"canceled","price":"18858.9","remaining_size":"0.045","type":"done","side":"buy","product_id":"BTC-USD","time":"2022-09-26T03:54:17.552222Z","sequence":46724808642},{"order_id":"0511871d-b64a-486f-b116-8163041eee74","order_type":"limit","size":"0.01504935","price":"18862.79","client_oid":"e4e73298-3d4e-11ed-8a20-0aa09ad95c5f","type":"received","side":"sell","product_id":"BTC-USD","time":"2022-09-26T03:54:17.553793Z","sequence":46724808643},{"price":"18862.79","order_id":"0511871d-b64a-486f-b116-8163041eee74","remaining_size":"0.01504935","type":"open","side":"sell","product_id":"BTC-USD","time":"2022-09-26T03:54:17.553793Z","sequence":46724808644},{"order_id":"79b45631-d093-4d5b-8a75-effcad0b9f66","order_type":"limit","size":"0.01207","price":"18858.91","client_oid":"20220926-0000-0000-0002-000000215301","type":"received","side":"sell","product_id":"BTC-USD","time":"2022-09-26T03:54:17.554077Z","sequence":46724808645},{"price":"18858.91","order_id":"79b45631-d093-4d5b-8a75-effcad0b9f66","remaining_size":"0.01207","type":"open","side":"sell","product_id":"BTC-USD","time":"2022-09-26T03:54:17.554077Z","sequence":46724808646},{"order_id":"79b45631-d093-4d5b-8a75-effcad0b9f66","reason":"canceled","price":"18858.91","remaining_size":"0.01207","type":"done","side":"sell","product_id":"BTC-USD","time":"2022-09-26T03:54:17.558048Z","sequence":46724808647},{"order_id":"1ab0be40-90d2-4425-bc97-0c44ae9437cf","order_type":"limit","size":"0.045","price":"18857.74","client_oid":"87641000-0000-0000-0000-636fd323bda7","type":"received","side":"buy","product_id":"BTC-USD","time":"2022-09-26T03:54:17.558308Z","sequence":46724808648},{"price":"18857.74","order_id":"1ab0be40-90d2-4425-bc97-0c44ae9437cf","remaining_size":"0.045","type":"open","side":"buy","product_id":"BTC-USD","time":"2022-09-26T03:54:17.558308Z","sequence":46724808649},{"order_id":"9c056a74-6a5f-4b32-b5d3-8cc5c9568c33","order_type":"limit","size":"0.02417","price":"18858.9","client_oid":"20220926-0000-0000-0004-000000213238","type":"received","side":"buy","product_id":"BTC-USD","time":"2022-09-26T03:54:17.558758Z","sequence":46724808650},{"price":"18858.9","order_id":"9c056a74-6a5f-4b32-b5d3-8cc5c9568c33","remaining_size":"0.02417","type":"open","side":"buy","product_id":"BTC-USD","time":"2022-09-26T03:54:17.558758Z","sequence":46724808651},{"order_id":"7e82a033-4d8e-4840-b616-0be0ffb0e7e1","order_type":"limit","size":"0.00107099","price":"19367.98","client_oid":"00000000-0000-0000-0005-e958faec78ca","type":"received","side":"sell","product_id":"BTC-USD","time":"2022-09-26T03:54:17.558827Z","sequence":46724808652},{"price":"19367.98","order_id":"7e82a033-4d8e-4840-b616-0be0ffb0e7e1","remaining_size":"0.00107099","type":"open","side":"sell","product_id":"BTC-USD","time":"2022-09-26T03:54:17.558827Z","sequence":46724808653},{"order_id":"9c056a74-6a5f-4b32-b5d3-8cc5c9568c33","reason":"canceled","price":"18858.9","remaining_size":"0.02417","type":"done","side":"buy","product_id":"BTC-USD","time":"2022-09-26T03:54:17.563168Z","sequence":46724808654},{"order_id":"1ab0be40-90d2-4425-bc97-0c44ae9437cf","reason":"canceled","price":"18857.74","remaining_size":"0.045","type":"done","side":"buy","product_id":"BTC-USD","time":"2022-09-26T03:54:17.565630Z","sequence":46724808655},{"order_id":"7240be68-38ec-43d0-bbe1-73d0deac1d70","reason":"canceled","price":"18858.91","remaining_size":"0.04493848","type":"done","side":"sell","product_id":"BTC-USD","time":"2022-09-26T03:54:17.566193Z","sequence":46724808656},{"order_id":"2c69d416-626c-40f3-9b86-b0938f6225ca","reason":"canceled","price":"18858.91","remaining_size":"0.00123467","type":"done","side":"sell","product_id":"BTC-USD","time":"2022-09-26T03:54:17.570010Z","sequence":46724808657},{"order_id":"b1f33302-4a17-4a46-8d29-35d62d2e6e99","order_type":"limit","size":"0.045","price":"18858.9","client_oid":"87641000-0000-0000-0000-636fd323eee7","type":"received","side":"buy","product_id":"BTC-USD","time":"2022-09-26T03:54:17.572145Z","sequence":46724808658},{"price":"18858.9","order_id":"b1f33302-4a17-4a46-8d29-35d62d2e6e99","remaining_size":"0.045","type":"open","side":"buy","product_id":"BTC-USD","time":"2022-09-26T03:54:17.572145Z","sequence":46724808659},{"order_id":"00a2b295-e184-497d-bac6-28d8ab9a1ee9","reason":"canceled","price":"18859.48","remaining_size":"0.04438912","type":"done","side":"sell","product_id":"BTC-USD","time":"2022-09-26T03:54:17.573889Z","sequence":46724808660},{"order_id":"20292416-58c7-4481-9ac6-784c6cef18a1","order_type":"limit","size":"0.02885227","price":"18856.72","client_oid":"735e5ae1-8b09-86fc-b089-c466b81f2fbe","type":"received","side":"buy","product_id":"BTC-USD","time":"2022-09-26T03:54:17.575919Z","sequence":46724808661},{"price":"18856.72","order_id":"20292416-58c7-4481-9ac6-784c6cef18a1","remaining_size":"0.02885227","type":"open","side":"buy","product_id":"BTC-USD","time":"2022-09-26T03:54:17.575919Z","sequence":46724808662},{"order_id":"91eccbcc-3d27-4e5c-bd4a-c2b551aaf1b2","order_type":"limit","size":"0.02417","price":"18858.9","client_oid":"20220926-0000-0000-0005-000000216030","type":"received","side":"buy","product_id":"BTC-USD","time":"2022-09-26T03:54:17.575955Z","sequence":46724808663},{"price":"18858.9","order_id":"91eccbcc-3d27-4e5c-bd4a-c2b551aaf1b2","remaining_size":"0.02417","type":"open","side":"buy","product_id":"BTC-USD","time":"2022-09-26T03:54:17.575955Z","sequence":46724808664},{"order_id":"193c9916-e23c-41de-925e-722638a58e3d","reason":"canceled","price":"18856.6","remaining_size":"0.02534887","type":"done","side":"buy","product_id":"BTC-USD","time":"2022-09-26T03:54:17.578082Z","sequence":46724808665},{"order_id":"b1f33302-4a17-4a46-8d29-35d62d2e6e99","reason":"canceled","price":"18858.9","remaining_size":"0.045","type":"done","side":"buy","product_id":"BTC-USD","time":"2022-09-26T03:54:17.578153Z","sequence":46724808666},{"order_id":"6382b5d4-8bb0-4048-8d87-f5a386e0c11e","reason":"canceled","price":"18859.48","remaining_size":"0.004","type":"done","side":"sell","product_id":"BTC-USD","time":"2022-09-26T03:54:17.578737Z","sequence":46724808667},{"order_id":"91eccbcc-3d27-4e5c-bd4a-c2b551aaf1b2","reason":"canceled","price":"18858.9","remaining_size":"0.02417","type":"done","side":"buy","product_id":"BTC-USD","time":"2022-09-26T03:54:17.580140Z","sequence":46724808668},{"order_id":"d048558e-3bb8-41fb-b4c4-ccda8bbfb666","reason":"canceled","price":"18861.16","remaining_size":"0.02575327","type":"done","side":"sell","product_id":"BTC-USD","time":"2022-09-26T03:54:17.582826Z","sequence":46724808669},{"order_id":"4faa57cf-f89b-4a73-bae3-931e99227573","order_type":"limit","size":"0.06142729","price":"18858.9","client_oid":"7fc04592-063a-43b2-b03c-34851d144f1c","type":"received","side":"buy","product_id":"BTC-USD","time":"2022-09-26T03:54:17.584163Z","sequence":46724808670},{"price":"18858.9","order_id":"4faa57cf-f89b-4a73-bae3-931e99227573","remaining_size":"0.06142729","type":"open","side":"buy","product_id":"BTC-USD","time":"2022-09-26T03:54:17.584163Z","sequence":46724808671},{"order_id":"01355b41-be92-4695-87b9-ebbb33d08ef8","order_type":"limit","size":"0.04432671","price":"18862.11","client_oid":"ef6684f6-1735-4f2c-8d9e-5d16ed539722","type":"received","side":"sell","product_id":"BTC-USD","time":"2022-09-26T03:54:17.584163Z","sequence":46724808672},{"price":"18862.11","order_id":"01355b41-be92-4695-87b9-ebbb33d08ef8","remaining_size":"0.04432671","type":"open","side":"sell","product_id":"BTC-USD","time":"2022-09-26T03:54:17.584163Z","sequence":46724808673},{"order_id":"9ab07601-6265-4b35-a918-3276a2528e7f","order_type":"limit","size":"0.02534887","price":"18856.79","client_oid":"00000000-0000-0000-0005-e958faec78cc","type":"received","side":"buy","product_id":"BTC-USD","time":"2022-09-26T03:54:17.584197Z","sequence":46724808674},{"price":"18856.79","order_id":"9ab07601-6265-4b35-a918-3276a2528e7f","remaining_size":"0.02534887","type":"open","side":"buy","product_id":"BTC-USD","time":"2022-09-26T03:54:17.584197Z","sequence":46724808675},{"order_id":"7887fe4f-d34a-4bbe-9aa3-065836a949c8","order_type":"limit","size":"0.045","price":"18857.74","client_oid":"87641000-0000-0000-0000-636fd32400cb","type":"received","side":"buy","product_id":"BTC-USD","time":"2022-09-26T03:54:17.585142Z","sequence":46724808676},{"price":"18857.74","order_id":"7887fe4f-d34a-4bbe-9aa3-065836a949c8","remaining_size":"0.045","type":"open","side":"buy","product_id":"BTC-USD","time":"2022-09-26T03:54:17.585142Z","sequence":46724808677},{"order_id":"a3bdccaa-3325-4001-9e77-d93db6ee32fd","order_type":"limit","size":"0.0240668","price":"18856.87","client_oid":"1d578a94-f813-ffdd-452a-4b1ce3015299","type":"received","side":"buy","product_id":"BTC-USD","time":"2022-09-26T03:54:17.588271Z","sequence":46724808678},{"price":"18856.87","order_id":"a3bdccaa-3325-4001-9e77-d93db6ee32fd","remaining_size":"0.0240668","type":"open","side":"buy","product_id":"BTC-USD","time":"2022-09-26T03:54:17.588271Z","sequence":46724808679},{"order_id":"12cea405-ab32-4379-9d6e-af48ae7309c3","order_type":"limit","size":"0.004","price":"18860.2","client_oid":"c9bf0bb3-7c91-450b-a7a9-402ad38ce2fc","type":"received","side":"sell","product_id":"BTC-USD","time":"2022-09-26T03:54:17.588375Z","sequence":46724808680},{"price":"18860.2","order_id":"12cea405-ab32-4379-9d6e-af48ae7309c3","remaining_size":"0.004","type":"open","side":"sell","product_id":"BTC-USD","time":"2022-09-26T03:54:17.588375Z","sequence":46724808681},{"order_id":"f053ab26-fe1a-4c35-9410-5b381653b303","reason":"canceled","price":"18856.25","remaining_size":"0.05376133","type":"done","side":"buy","product_id":"BTC-USD","time":"2022-09-26T03:54:17.588424Z","sequence":46724808682},{"order_id":"5b5c7a88-a678-4542-badc-81de0016755d","order_type":"limit","size":"0.946822","price":"18855.79","client_oid":"8cef8801-45f5-433f-bd7f-20437a79ef2b","type":"received","side":"buy","product_id":"BTC-USD","time":"2022-09-26T03:54:17.588554Z","sequence":46724808683},{"price":"18855.79","order_id":"5b5c7a88-a678-4542-badc-81de0016755d","remaining_size":"0.946822","type":"open","side":"buy","product_id":"BTC-USD","time":"2022-09-26T03:54:17.588554Z","sequence":46724808684},{"order_id":"7a4f23c6-21b1-48e7-a475-55eacdcc9657","order_type":"limit","size":"0.94945621","price":"18851.8","client_oid":"3f9a6db4-97b3-4187-b260-ab508c807860","type":"received","side":"buy","product_id":"BTC-USD","time":"2022-09-26T03:54:17.588770Z","sequence":46724808685},{"price":"18851.8","order_id":"7a4f23c6-21b1-48e7-a475-55eacdcc9657","remaining_size":"0.94945621","type":"open","side":"buy","product_id":"BTC-USD","time":"2022-09-26T03:54:17.588770Z","sequence":46724808686},{"order_id":"e12fd0e0-4dc7-46cb-b056-0ce2c8d70b02","order_type":"limit","size":"0.02534887","price":"18862.03","client_oid":"00000000-0000-0000-0005-e958faec78cd","type":"received","side":"sell","product_id":"BTC-USD","time":"2022-09-26T03:54:17.588859Z","sequence":46724808687},{"price":"18862.03","order_id":"e12fd0e0-4dc7-46cb-b056-0ce2c8d70b02","remaining_size":"0.02534887","type":"open","side":"sell","product_id":"BTC-USD","time":"2022-09-26T03:54:17.588859Z","sequence":46724808688},{"order_id":"91147900-c5c2-495f-b91c-f7847cbb348c","order_type":"limit","size":"0.03423068","price":"18856.9","client_oid":"93ff002c-76f4-f7ce-5298-2b63885b767c","type":"received","side":"buy","product_id":"BTC-USD","time":"2022-09-26T03:54:17.588881Z","sequence":46724808689},{"price":"18856.9","order_id":"91147900-c5c2-495f-b91c-f7847cbb348c","remaining_size":"0.03423068","type":"open","side":"buy","product_id":"BTC-USD","time":"2022-09-26T03:54:17.588881Z","sequence":46724808690},{"order_id":"7887fe4f-d34a-4bbe-9aa3-065836a949c8","reason":"canceled","price":"18857.74","remaining_size":"0.045","type":"done","side":"buy","product_id":"BTC-USD","time":"2022-09-26T03:54:17.591174Z","sequence":46724808691},{"order_id":"e12fd0e0-4dc7-46cb-b056-0ce2c8d70b02","reason":"canceled","price":"18862.03","remaining_size":"0.02534887","type":"done","side":"sell","product_id":"BTC-USD","time":"2022-09-26T03:54:17.593486Z","sequence":46724808692},{"order_id":"9ab07601-6265-4b35-a918-3276a2528e7f","reason":"canceled","price":"18856.79","remaining_size":"0.02534887","type":"done","side":"buy","product_id":"BTC-USD","time":"2022-09-26T03:54:17.594049Z","sequence":46724808693},{"order_id":"0511871d-b64a-486f-b116-8163041eee74","reason":"canceled","price":"18862.79","remaining_size":"0.01504935","type":"done","side":"sell","product_id":"BTC-USD","time":"2022-09-26T03:54:17.594728Z","sequence":46724808694},{"order_id":"a76bc6c1-5a6e-496a-aa24-bf91f1e35b32","order_type":"limit","size":"0.045","price":"18858.93","client_oid":"97641000-0000-0000-0000-636fd323e260","type":"received","side":"buy","product_id":"BTC-USD","time":"2022-09-26T03:54:17.596378Z","sequence":46724808695},{"price":"18858.93","order_id":"a76bc6c1-5a6e-496a-aa24-bf91f1e35b32","remaining_size":"0.045","type":"open","side":"buy","product_id":"BTC-USD","time":"2022-09-26T03:54:17.596378Z","sequence":46724808696},{"order_id":"3d2bd450-b350-4832-80f8-744ba9cd6605","order_type":"limit","size":"0.02534887","price":"18862.03","client_oid":"00000000-0000-0000-0005-e958faec78ce","type":"received","side":"sell","product_id":"BTC-USD","time":"2022-09-26T03:54:17.597098Z","sequence":46724808697},{"price":"18862.03","order_id":"3d2bd450-b350-4832-80f8-744ba9cd6605","remaining_size":"0.02534887","type":"open","side":"sell","product_id":"BTC-USD","time":"2022-09-26T03:54:17.597098Z","sequence":46724808698},{"order_id":"936d14d4-f5c4-4aba-b6a7-18b57bf4f5a4","order_type":"limit","size":"0.06052016","price":"18858.95","client_oid":"993666e6-a379-4708-8f53-b06cbfcf437f","type":"received","side":"buy","product_id":"BTC-USD","time":"2022-09-26T03:54:17.600378Z","sequence":46724808699},{"price":"18858.95","order_id":"936d14d4-f5c4-4aba-b6a7-18b57bf4f5a4","remaining_size":"0.06052016","type":"open","side":"buy","product_id":"BTC-USD","time":"2022-09-26T03:54:17.600378Z","sequence":46724808700},{"order_id":"a606771c-e6bd-44a0-9f36-691c191a4397","order_type":"limit","size":"0.02534887","price":"18856.88","client_oid":"00000000-0000-0000-0005-e958faec78cf","type":"received","side":"buy","product_id":"BTC-USD","time":"2022-09-26T03:54:17.600404Z","sequence":46724808701},{"price":"18856.88","order_id":"a606771c-e6bd-44a0-9f36-691c191a4397","remaining_size":"0.02534887","type":"open","side":"buy","product_id":"BTC-USD","time":"2022-09-26T03:54:17.600404Z","sequence":46724808702},{"order_id":"3d2bd450-b350-4832-80f8-744ba9cd6605","reason":"canceled","price":"18862.03","remaining_size":"0.02534887","type":"done","side":"sell","product_id":"BTC-USD","time":"2022-09-26T03:54:17.601982Z","sequence":46724808703},{"order_id":"a606771c-e6bd-44a0-9f36-691c191a4397","reason":"canceled","price":"18856.88","remaining_size":"0.02534887","type":"done","side":"buy","product_id":"BTC-USD","time":"2022-09-26T03:54:17.603524Z","sequence":46724808704},{"order_id":"681e81ef-cffd-4def-b573-e090f3c5eaf1","order_type":"limit","size":"0.02534887","price":"18856.91","client_oid":"00000000-0000-0000-0005-e958faec78d0","type":"received","side":"buy","product_id":"BTC-USD","time":"2022-09-26T03:54:17.604732Z","sequence":46724808705},{"price":"18856.91","order_id":"681e81ef-cffd-4def-b573-e090f3c5eaf1","remaining_size":"0.02534887","type":"open","side":"buy","product_id":"BTC-USD","time":"2022-09-26T03:54:17.604732Z","sequence":46724808706},{"order_id":"5f02eefc-003f-499f-9bd7-c4d3aa462bf1","order_type":"limit","size":"0.02534887","price":"18861.81","client_oid":"00000000-0000-0000-0005-e958faec78d1","type":"received","side":"sell","product_id":"BTC-USD","time":"2022-09-26T03:54:17.604755Z","sequence":46724808707},{"price":"18861.81","order_id":"5f02eefc-003f-499f-9bd7-c4d3aa462bf1","remaining_size":"0.02534887","type":"open","side":"sell","product_id":"BTC-USD","time":"2022-09-26T03:54:17.604755Z","sequence":46724808708},{"order_id":"34a60e94-e6a1-4a05-a15c-7e4d6c016d1b","reason":"canceled","price":"18862.24","remaining_size":"0.1","type":"done","side":"sell","product_id":"BTC-USD","time":"2022-09-26T03:54:17.606688Z","sequence":46724808709},{"order_id":"a76bc6c1-5a6e-496a-aa24-bf91f1e35b32","reason":"canceled","price":"18858.93","remaining_size":"0.045","type":"done","side":"buy","product_id":"BTC-USD","time":"2022-09-26T03:54:17.607087Z","sequence":46724808710},{"order_id":"d11bad0e-d917-46e7-bc0d-8f6e63aed88e","order_type":"limit","size":"0.00228234","price":"18858.94","client_oid":"e4ef6973-3d4e-11ed-8a20-0aa09ad95c5f","type":"received","side":"buy","product_id":"BTC-USD","time":"2022-09-26T03:54:17.608308Z","sequence":46724808711},{"price":"18858.94","order_id":"d11bad0e-d917-46e7-bc0d-8f6e63aed88e","remaining_size":"0.00228234","type":"open","side":"buy","product_id":"BTC-USD","time":"2022-09-26T03:54:17.608308Z","sequence":46724808712},{"order_id":"39046ec6-fe72-46de-b3c3-6c016dc1a88d","order_type":"limit","size":"0.01504935","price":"18862.79","client_oid":"e4ef95d4-3d4e-11ed-8a20-0aa09ad95c5f","type":"received","side":"sell","product_id":"BTC-USD","time":"2022-09-26T03:54:17.608580Z","sequence":46724808713},{"price":"18862.79","order_id":"39046ec6-fe72-46de-b3c3-6c016dc1a88d","remaining_size":"0.01504935","type":"open","side":"sell","product_id":"BTC-USD","time":"2022-09-26T03:54:17.608580Z","sequence":46724808714},{"order_id":"502604e1-43ab-45f0-ac01-10ebfc1ee8bb","reason":"canceled","price":"18854.77","remaining_size":"0.02353006","type":"done","side":"buy","product_id":"BTC-USD","time":"2022-09-26T03:54:17.609705Z","sequence":46724808715},{"order_id":"91921e80-1403-493d-bd8c-31a3fc2c5839","reason":"canceled","price":"18858.9","remaining_size":"0.00228234","type":"done","side":"buy","product_id":"BTC-USD","time":"2022-09-26T03:54:17.611969Z","sequence":46724808716},{"order_id":"394f082a-bced-47ee-b0e8-fbd297d9062a","order_type":"limit","size":"0.03563449","price":"18856.9","client_oid":"6bc2a4c4-a979-e80e-821d-9d0083d2e730","type":"received","side":"buy","product_id":"BTC-USD","time":"2022-09-26T03:54:17.612526Z","sequence":46724808717},{"price":"18856.9","order_id":"394f082a-bced-47ee-b0e8-fbd297d9062a","remaining_size":"0.03563449","type":"open","side":"buy","product_id":"BTC-USD","time":"2022-09-26T03:54:17.612526Z","sequence":46724808718},{"order_id":"08128f48-8b5f-47a0-81a5-e7be2bcacf13","order_type":"limit","size":"0.045","price":"18858.98","client_oid":"97641000-0000-0000-0000-636fd32400cb","type":"received","side":"buy","product_id":"BTC-USD","time":"2022-09-26T03:54:17.612771Z","sequence":46724808719},{"price":"18858.98","order_id":"08128f48-8b5f-47a0-81a5-e7be2bcacf13","remaining_size":"0.045","type":"open","side":"buy","product_id":"BTC-USD","time":"2022-09-26T03:54:17.612771Z","sequence":46724808720},{"order_id":"026d7d38-1dac-4064-837b-113b16455c50","order_type":"limit","size":"0.00228234","price":"18858.96","client_oid":"e4f03a27-3d4e-11ed-8a20-0aa09ad95c5f","type":"received","side":"buy","product_id":"BTC-USD","time":"2022-09-26T03:54:17.620795Z","sequence":46724808721},{"price":"18858.96","order_id":"026d7d38-1dac-4064-837b-113b16455c50","remaining_size":"0.00228234","type":"open","side":"buy","product_id":"BTC-USD","time":"2022-09-26T03:54:17.620795Z","sequence":46724808722},{"order_id":"3097007c-b5be-46df-b731-043cb7f6c876","order_type":"limit","size":"0.02985331","price":"18857.02","client_oid":"e468f2fc-7d4c-dba5-528c-fb1a358d9159","type":"received","side":"buy","product_id":"BTC-USD","time":"2022-09-26T03:54:17.621161Z","sequence":46724808723},{"price":"18857.02","order_id":"3097007c-b5be-46df-b731-043cb7f6c876","remaining_size":"0.02985331","type":"open","side":"buy","product_id":"BTC-USD","time":"2022-09-26T03:54:17.621161Z","sequence":46724808724},{"order_id":"9bacdb5a-d781-4558-a41d-bbdc0f08b27e","order_type":"limit","size":"0.03626832","price":"18856.99","client_oid":"a57f7cbf-866f-8115-0d8f-e53cb9d6578e","type":"received","side":"buy","product_id":"BTC-USD","time":"2022-09-26T03:54:17.624846Z","sequence":46724808725},{"price":"18856.99","order_id":"9bacdb5a-d781-4558-a41d-bbdc0f08b27e","remaining_size":"0.03626832","type":"open","side":"buy","product_id":"BTC-USD","time":"2022-09-26T03:54:17.624846Z","sequence":46724808726},{"order_id":"10ea1bbd-1e33-47c4-8009-16a8271b7edc","reason":"canceled","price":"18855.39","remaining_size":"0.0242582","type":"done","side":"buy","product_id":"BTC-USD","time":"2022-09-26T03:54:17.625190Z","sequence":46724808727},{"order_id":"681e81ef-cffd-4def-b573-e090f3c5eaf1","reason":"canceled","price":"18856.91","remaining_size":"0.02534887","type":"done","side":"buy","product_id":"BTC-USD","time":"2022-09-26T03:54:17.627416Z","sequence":46724808728},{"order_id":"6af017de-637a-43fe-9da4-2d66030b8e30","order_type":"limit","size":"0.00228234","price":"18858.99","client_oid":"e4f1efde-3d4e-11ed-8a20-0aa09ad95c5f","type":"received","side":"buy","product_id":"BTC-USD","time":"2022-09-26T03:54:17.628842Z","sequence":46724808729},{"price":"18858.99","order_id":"6af017de-637a-43fe-9da4-2d66030b8e30","remaining_size":"0.00228234","type":"open","side":"buy","product_id":"BTC-USD","time":"2022-09-26T03:54:17.628842Z","sequence":46724808730},{"order_id":"0e350e6b-7401-4f2d-9dbb-32221b925cea","order_type":"limit","size":"0.02534887","price":"18857.03","client_oid":"00000000-0000-0000-0005-e958faec78d3","type":"received","side":"buy","product_id":"BTC-USD","time":"2022-09-26T03:54:17.633384Z","sequence":46724808731},{"price":"18857.03","order_id":"0e350e6b-7401-4f2d-9dbb-32221b925cea","remaining_size":"0.02534887","type":"open","side":"buy","product_id":"BTC-USD","time":"2022-09-26T03:54:17.633384Z","sequence":46724808732},{"order_id":"11d183f1-902e-41e8-a050-6606749029b8","reason":"canceled","price":"18855.78","remaining_size":"0.03398871","type":"done","side":"buy","product_id":"BTC-USD","time":"2022-09-26T03:54:17.634915Z","sequence":46724808733},{"order_id":"679f0876-6fba-40bf-8158-4f961be78240","order_type":"limit","size":"0.03583602","price":"18857.06","client_oid":"ca8e8b26-a554-47e2-99cc-d8f83bd2c01f","type":"received","side":"buy","product_id":"BTC-USD","time":"2022-09-26T03:54:17.646494Z","sequence":46724808734},{"price":"18857.06","order_id":"679f0876-6fba-40bf-8158-4f961be78240","remaining_size":"0.03583602","type":"open","side":"buy","product_id":"BTC-USD","time":"2022-09-26T03:54:17.646494Z","sequence":46724808735},{"order_id":"85562156-9159-40ec-984c-a96340011a1a","order_type":"limit","size":"0.02990808","price":"18857.11","client_oid":"91b68b5e-bf90-1c16-c3f5-dada0ca80d66","type":"received","side":"buy","product_id":"BTC-USD","time":"2022-09-26T03:54:17.650145Z","sequence":46724808736},{"price":"18857.11","order_id":"85562156-9159-40ec-984c-a96340011a1a","remaining_size":"0.02990808","type":"open","side":"buy","product_id":"BTC-USD","time":"2022-09-26T03:54:17.650145Z","sequence":46724808737},{"order_id":"0e350e6b-7401-4f2d-9dbb-32221b925cea","reason":"canceled","price":"18857.03","remaining_size":"0.02534887","type":"done","side":"buy","product_id":"BTC-USD","time":"2022-09-26T03:54:17.652482Z","sequence":46724808738},{"order_id":"813c86a5-e1c4-4d6c-9ba0-29f4b5dc9eb2","reason":"canceled","price":"18855.78","remaining_size":"0.02684066","type":"done","side":"buy","product_id":"BTC-USD","time":"2022-09-26T03:54:17.654109Z","sequence":46724808739},{"order_id":"b9d1336d-3591-4438-b22f-caff583347d0","order_type":"limit","size":"0.02534887","price":"18857.07","client_oid":"00000000-0000-0000-0005-e958faec78d5","type":"received","side":"buy","product_id":"BTC-USD","time":"2022-09-26T03:54:17.657959Z","sequence":46724808740},{"price":"18857.07","order_id":"b9d1336d-3591-4438-b22f-caff583347d0","remaining_size":"0.02534887","type":"open","side":"buy","product_id":"BTC-USD","time":"2022-09-26T03:54:17.657959Z","sequence":46724808741},{"order_id":"b9d1336d-3591-4438-b22f-caff583347d0","reason":"canceled","price":"18857.07","remaining_size":"0.02534887","type":"done","side":"buy","product_id":"BTC-USD","time":"2022-09-26T03:54:17.660980Z","sequence":46724808742},{"order_id":"a5874513-d237-4547-9c8d-aeea6ab126ac","order_type":"limit","size":"0.02534887","price":"18857.12","client_oid":"00000000-0000-0000-0005-e958faec78d6","type":"received","side":"buy","product_id":"BTC-USD","time":"2022-09-26T03:54:17.666180Z","sequence":46724808743},{"price":"18857.12","order_id":"a5874513-d237-4547-9c8d-aeea6ab126ac","remaining_size":"0.02534887","type":"open","side":"buy","product_id":"BTC-USD","time":"2022-09-26T03:54:17.666180Z","sequence":46724808744},{"order_id":"81e92bb8-72af-4902-a008-db67e39bee9a","reason":"canceled","price":"18856.27","remaining_size":"0.02848313","type":"done","side":"buy","product_id":"BTC-USD","time":"2022-09-26T03:54:17.668394Z","sequence":46724808745},{"order_id":"54089587-974d-45af-ad3f-ef05cf517d72","reason":"canceled","price":"18860.3","remaining_size":"0.0028522","type":"done","side":"sell","product_id":"BTC-USD","time":"2022-09-26T03:54:17.669866Z","sequence":46724808746},{"order_id":"d8647b57-71ab-4aa6-b1ca-da2335df9860","reason":"canceled","price":"18856.28","remaining_size":"0.02443875","type":"done","side":"buy","product_id":"BTC-USD","time":"2022-09-26T03:54:17.679401Z","sequence":46724808747},{"order_id":"f843922f-38e0-4a50-8d31-05eb2c6d1ee6","order_type":"limit","size":"0.05167328","price":"18858.99","client_oid":"5daf0bb1-7d7e-4f5c-af9a-6efa801251e1","type":"received","side":"buy","product_id":"BTC-USD","time":"2022-09-26T03:54:17.683148Z","sequence":46724808748},{"price":"18858.99","order_id":"f843922f-38e0-4a50-8d31-05eb2c6d1ee6","remaining_size":"0.05167328","type":"open","side":"buy","product_id":"BTC-USD","time":"2022-09-26T03:54:17.683148Z","sequence":46724808749},{"order_id":"d99d6918-2594-4155-bb22-7387a2b0d3e2","order_type":"limit","size":"0.01464745","price":"18857.14","client_oid":"ae7bb60d-692a-6510-0836-63733f4b74ad","type":"received","side":"buy","product_id":"BTC-USD","time":"2022-09-26T03:54:17.683253Z","sequence":46724808750},{"price":"18857.14","order_id":"d99d6918-2594-4155-bb22-7387a2b0d3e2","remaining_size":"0.01464745","type":"open","side":"buy","product_id":"BTC-USD","time":"2022-09-26T03:54:17.683253Z","sequence":46724808751},{"order_id":"08128f48-8b5f-47a0-81a5-e7be2bcacf13","reason":"canceled","price":"18858.98","remaining_size":"0.045","type":"done","side":"buy","product_id":"BTC-USD","time":"2022-09-26T03:54:17.689660Z","sequence":46724808752},{"order_id":"a5874513-d237-4547-9c8d-aeea6ab126ac","reason":"canceled","price":"18857.12","remaining_size":"0.02534887","type":"done","side":"buy","product_id":"BTC-USD","time":"2022-09-26T03:54:17.689745Z","sequence":46724808753},{"order_id":"936d14d4-f5c4-4aba-b6a7-18b57bf4f5a4","reason":"canceled","price":"18858.95","remaining_size":"0.06052016","type":"done","side":"buy","product_id":"BTC-USD","time":"2022-09-26T03:54:17.691358Z","sequence":46724808754},{"order_id":"4faa57cf-f89b-4a73-bae3-931e99227573","reason":"canceled","price":"18858.9","remaining_size":"0.06142729","type":"done","side":"buy","product_id":"BTC-USD","time":"2022-09-26T03:54:17.695168Z","sequence":46724808755},{"order_id":"3e1bc3e8-80f1-4948-9885-eb8bdb8aa9e8","order_type":"limit","size":"0.045","price":"18859.02","client_oid":"18641000-0000-0000-0000-636fd323e260","type":"received","side":"buy","product_id":"BTC-USD","time":"2022-09-26T03:54:17.696714Z","sequence":46724808756},{"price":"18859.02","order_id":"3e1bc3e8-80f1-4948-9885-eb8bdb8aa9e8","remaining_size":"0.045","type":"open","side":"buy","product_id":"BTC-USD","time":"2022-09-26T03:54:17.696714Z","sequence":46724808757},{"order_id":"1077f57e-8bb2-4321-b807-076b745aaf4c","order_type":"limit","size":"0.02534887","price":"18857.15","client_oid":"00000000-0000-0000-0005-e958faec78d8","type":"received","side":"buy","product_id":"BTC-USD","time":"2022-09-26T03:54:17.697216Z","sequence":46724808758},{"price":"18857.15","order_id":"1077f57e-8bb2-4321-b807-076b745aaf4c","remaining_size":"0.02534887","type":"open","side":"buy","product_id":"BTC-USD","time":"2022-09-26T03:54:17.697216Z","sequence":46724808759},{"order_id":"5f02eefc-003f-499f-9bd7-c4d3aa462bf1","reason":"canceled","price":"18861.81","remaining_size":"0.02534887","type":"done","side":"sell","product_id":"BTC-USD","time":"2022-09-26T03:54:17.701534Z","sequence":46724808760},{"order_id":"d11bad0e-d917-46e7-bc0d-8f6e63aed88e","reason":"canceled","price":"18858.94","remaining_size":"0.00228234","type":"done","side":"buy","product_id":"BTC-USD","time":"2022-09-26T03:54:17.703277Z","sequence":46724808761},{"order_id":"026d7d38-1dac-4064-837b-113b16455c50","reason":"canceled","price":"18858.96","remaining_size":"0.00228234","type":"done","side":"buy","product_id":"BTC-USD","time":"2022-09-26T03:54:17.707455Z","sequence":46724808762},{"order_id":"53ca6e45-fae7-41ba-9377-5d5f67805911","order_type":"limit","size":"0.02534887","price":"18861.7","client_oid":"00000000-0000-0000-0005-e958faec78d9","type":"received","side":"sell","product_id":"BTC-USD","time":"2022-09-26T03:54:17.708182Z","sequence":46724808763},{"price":"18861.7","order_id":"53ca6e45-fae7-41ba-9377-5d5f67805911","remaining_size":"0.02534887","type":"open","side":"sell","product_id":"BTC-USD","time":"2022-09-26T03:54:17.708182Z","sequence":46724808764},{"order_id":"f2003a7e-f817-41e6-a674-3c29fe343e25","order_type":"limit","size":"0.00228234","price":"18859.03","client_oid":"e500b80d-3d4e-11ed-8a20-0aa09ad95c5f","type":"received","side":"buy","product_id":"BTC-USD","time":"2022-09-26T03:54:17.720098Z","sequence":46724808765},{"price":"18859.03","order_id":"f2003a7e-f817-41e6-a674-3c29fe343e25","remaining_size":"0.00228234","type":"open","side":"buy","product_id":"BTC-USD","time":"2022-09-26T03:54:17.720098Z","sequence":46724808766},{"order_id":"9fb433ae-cabd-4ae0-a507-fc88e31bcfa7","reason":"canceled","price":"18856.38","remaining_size":"0.01305696","type":"done","side":"buy","product_id":"BTC-USD","time":"2022-09-26T03:54:17.722802Z","sequence":46724808767},{"order_id":"6af017de-637a-43fe-9da4-2d66030b8e30","reason":"canceled","price":"18858.99","remaining_size":"0.00228234","type":"done","side":"buy","product_id":"BTC-USD","time":"2022-09-26T03:54:17.725469Z","sequence":46724808768},{"order_id":"53ca6e45-fae7-41ba-9377-5d5f67805911","reason":"canceled","price":"18861.7","remaining_size":"0.02534887","type":"done","side":"sell","product_id":"BTC-USD","time":"2022-09-26T03:54:17.728055Z","sequence":46724808769},{"order_id":"909c8b5a-026e-4bc2-b170-3a1364a4ff57","order_type":"limit","size":"0.02634313","price":"18857.23","client_oid":"821eb85e-ffe7-d60b-dda1-181b57e86ccd","type":"received","side":"buy","product_id":"BTC-USD","time":"2022-09-26T03:54:17.728830Z","sequence":46724808770},{"price":"18857.23","order_id":"909c8b5a-026e-4bc2-b170-3a1364a4ff57","remaining_size":"0.02634313","type":"open","side":"buy","product_id":"BTC-USD","time":"2022-09-26T03:54:17.728830Z","sequence":46724808771},{"order_id":"b9686ad1-621b-4603-8fb0-7ecef088c1f7","order_type":"limit","size":"0.02534887","price":"18861.69","client_oid":"00000000-0000-0000-0005-e958faec78db","type":"received","side":"sell","product_id":"BTC-USD","time":"2022-09-26T03:54:17.736574Z","sequence":46724808772},{"price":"18861.69","order_id":"b9686ad1-621b-4603-8fb0-7ecef088c1f7","remaining_size":"0.02534887","type":"open","side":"sell","product_id":"BTC-USD","time":"2022-09-26T03:54:17.736574Z","sequence":46724808773},{"order_id":"909c8b5a-026e-4bc2-b170-3a1364a4ff57","reason":"canceled","price":"18857.23","remaining_size":"0.02634313","type":"done","side":"buy","product_id":"BTC-USD","time":"2022-09-26T03:54:17.821448Z","sequence":46724808774},{"order_id":"f843922f-38e0-4a50-8d31-05eb2c6d1ee6","reason":"canceled","price":"18858.99","remaining_size":"0.05167328","type":"done","side":"buy","product_id":"BTC-USD","time":"2022-09-26T03:54:17.830558Z","sequence":46724808775},{"order_id":"c8917086-d768-4db3-ba5f-9cc18b3dbbcd","order_type":"limit","size":"0.1","price":"18862.35","client_oid":"e511dd80-3d4e-11ed-8b5d-abb0b41c20d0","type":"received","side":"sell","product_id":"BTC-USD","time":"2022-09-26T03:54:17.834250Z","sequence":46724808776},{"price":"18862.35","order_id":"c8917086-d768-4db3-ba5f-9cc18b3dbbcd","remaining_size":"0.1","type":"open","side":"sell","product_id":"BTC-USD","time":"2022-09-26T03:54:17.834250Z","sequence":46724808777},{"order_id":"56e4fc88-aaf5-49be-bb7e-6f4aa7626b6e","order_type":"limit","size":"0.1","price":"18856.57","client_oid":"e511b66e-3d4e-11ed-8b5d-abb0b41c20d0","type":"received","side":"buy","product_id":"BTC-USD","time":"2022-09-26T03:54:17.834380Z","sequence":46724808778},{"price":"18856.57","order_id":"56e4fc88-aaf5-49be-bb7e-6f4aa7626b6e","remaining_size":"0.1","type":"open","side":"buy","product_id":"BTC-USD","time":"2022-09-26T03:54:17.834380Z","sequence":46724808779},{"order_id":"0e1f0e91-3afb-4f50-8657-a208ac3dd892","reason":"canceled","price":"18856.56","remaining_size":"0.1","type":"done","side":"buy","product_id":"BTC-USD","time":"2022-09-26T03:54:17.837428Z","sequence":46724808780},{"order_id":"b9686ad1-621b-4603-8fb0-7ecef088c1f7","reason":"canceled","price":"18861.69","remaining_size":"0.02534887","type":"done","side":"sell","product_id":"BTC-USD","time":"2022-09-26T03:54:17.838021Z","sequence":46724808781},{"order_id":"3e1bc3e8-80f1-4948-9885-eb8bdb8aa9e8","reason":"canceled","price":"18859.02","remaining_size":"0.045","type":"done","side":"buy","product_id":"BTC-USD","time":"2022-09-26T03:54:17.839823Z","sequence":46724808782},{"order_id":"89eebdde-7b48-40ed-80c3-adaa491df7cb","reason":"canceled","price":"18861.84","remaining_size":"0.08","type":"done","side":"sell","product_id":"BTC-USD","time":"2022-09-26T03:54:17.840781Z","sequence":46724808783},{"order_id":"7fd8d330-a0fa-41c9-baa9-47e70962c7f4","order_type":"limit","size":"0.045","price":"18857.74","client_oid":"38641000-0000-0000-0000-636fd323bda7","type":"received","side":"buy","product_id":"BTC-USD","time":"2022-09-26T03:54:17.846295Z","sequence":46724808784},{"price":"18857.74","order_id":"7fd8d330-a0fa-41c9-baa9-47e70962c7f4","remaining_size":"0.045","type":"open","side":"buy","product_id":"BTC-USD","time":"2022-09-26T03:54:17.846295Z","sequence":46724808785},{"order_id":"e9082e06-cea7-4fb7-aaa7-083c206253a3","order_type":"limit","size":"0.04432671","price":"18859.04","client_oid":"1d4995ff-0af5-4dc1-b199-fab239796770","type":"received","side":"sell","product_id":"BTC-USD","time":"2022-09-26T03:54:17.846424Z","sequence":46724808786},{"price":"18859.04","order_id":"e9082e06-cea7-4fb7-aaa7-083c206253a3","remaining_size":"0.04432671","type":"open","side":"sell","product_id":"BTC-USD","time":"2022-09-26T03:54:17.846424Z","sequence":46724808787},{"order_id":"7b6ef6d0-b1a8-4349-be0e-623eaa6fb560","order_type":"limit","size":"0.02475565","price":"18857.82","client_oid":"dce15e49-2904-3b90-aac6-af3c77e207f3","type":"received","side":"buy","product_id":"BTC-USD","time":"2022-09-26T03:54:17.846434Z","sequence":46724808788},{"price":"18857.82","order_id":"7b6ef6d0-b1a8-4349-be0e-623eaa6fb560","remaining_size":"0.02475565","type":"open","side":"buy","product_id":"BTC-USD","time":"2022-09-26T03:54:17.846434Z","sequence":46724808789},{"order_id":"793b402a-2627-4ac7-928b-17b9b9c57b12","order_type":"limit","size":"0.0259114","price":"18857.18","client_oid":"9ff914c2-a8d3-f798-dadd-ace6a403b264","type":"received","side":"buy","product_id":"BTC-USD","time":"2022-09-26T03:54:17.846446Z","sequence":46724808790},{"price":"18857.18","order_id":"793b402a-2627-4ac7-928b-17b9b9c57b12","remaining_size":"0.0259114","type":"open","side":"buy","product_id":"BTC-USD","time":"2022-09-26T03:54:17.846446Z","sequence":46724808791},{"order_id":"535c53c5-538e-4716-ab97-4132e935b0d9","reason":"canceled","price":"18861.98","remaining_size":"0.00172685","type":"done","side":"sell","product_id":"BTC-USD","time":"2022-09-26T03:54:17.846555Z","sequence":46724808792},{"order_id":"c014c513-d650-42ca-b74a-e93ac6d41a39","reason":"canceled","price":"18856.77","remaining_size":"0.02203617","type":"done","side":"buy","product_id":"BTC-USD","time":"2022-09-26T03:54:17.846661Z","sequence":46724808793},{"order_id":"ec4c8e53-a973-4352-9773-1cd3ac4dacd0","order_type":"limit","size":"0.02534887","price":"18861.63","client_oid":"00000000-0000-0000-0005-e958faec78e1","type":"received","side":"sell","product_id":"BTC-USD","time":"2022-09-26T03:54:17.846842Z","sequence":46724808794},{"price":"18861.63","order_id":"ec4c8e53-a973-4352-9773-1cd3ac4dacd0","remaining_size":"0.02534887","type":"open","side":"sell","product_id":"BTC-USD","time":"2022-09-26T03:54:17.846842Z","sequence":46724808795},{"order_id":"c36029fc-c922-40eb-8b10-242830260cf4","reason":"canceled","price":"18856.31","remaining_size":"0.02738934","type":"done","side":"buy","product_id":"BTC-USD","time":"2022-09-26T03:54:17.847188Z","sequence":46724808796},{"order_id":"a3bdccaa-3325-4001-9e77-d93db6ee32fd","reason":"canceled","price":"18856.87","remaining_size":"0.0240668","type":"done","side":"buy","product_id":"BTC-USD","time":"2022-09-26T03:54:17.850140Z","sequence":46724808797},{"order_id":"394f082a-bced-47ee-b0e8-fbd297d9062a","reason":"canceled","price":"18856.9","remaining_size":"0.03563449","type":"done","side":"buy","product_id":"BTC-USD","time":"2022-09-26T03:54:17.850140Z","sequence":46724808798},{"order_id":"aa72ddb2-33a8-451c-8a14-a5d53585edd9","reason":"canceled","price":"18861.7","remaining_size":"0.02394406","type":"done","side":"sell","product_id":"BTC-USD","time":"2022-09-26T03:54:17.850738Z","sequence":46724808799},{"order_id":"1ce1242a-213d-4a62-852b-2eaa09ef3d36","reason":"canceled","price":"18861.73","remaining_size":"0.0246947","type":"done","side":"sell","product_id":"BTC-USD","time":"2022-09-26T03:54:17.850738Z","sequence":46724808800},{"order_id":"29ed3edb-10db-428a-874a-e93c82aab7b8","reason":"canceled","price":"18861.64","remaining_size":"0.02046431","type":"done","side":"sell","product_id":"BTC-USD","time":"2022-09-26T03:54:17.850761Z","sequence":46724808801},{"order_id":"ec4c8e53-a973-4352-9773-1cd3ac4dacd0","reason":"canceled","price":"18861.63","remaining_size":"0.02534887","type":"done","side":"sell","product_id":"BTC-USD","time":"2022-09-26T03:54:17.852900Z","sequence":46724808802},{"order_id":"1077f57e-8bb2-4321-b807-076b745aaf4c","reason":"canceled","price":"18857.15","remaining_size":"0.02534887","type":"done","side":"buy","product_id":"BTC-USD","time":"2022-09-26T03:54:17.852981Z","sequence":46724808803},{"order_id":"7fd8d330-a0fa-41c9-baa9-47e70962c7f4","reason":"canceled","price":"18857.74","remaining_size":"0.045","type":"done","side":"buy","product_id":"BTC-USD","time":"2022-09-26T03:54:17.853200Z","sequence":46724808804},{"order_id":"75412aae-35c6-419e-ac1c-9310e292712d","order_type":"limit","size":"0.02854089","price":"18857.21","client_oid":"0661c3fd-834c-dbd5-aa15-310d6978d2c5","type":"received","side":"buy","product_id":"BTC-USD","time":"2022-09-26T03:54:17.855201Z","sequence":46724808805},{"price":"18857.21","order_id":"75412aae-35c6-419e-ac1c-9310e292712d","remaining_size":"0.02854089","type":"open","side":"buy","product_id":"BTC-USD","time":"2022-09-26T03:54:17.855201Z","sequence":46724808806},{"order_id":"21d2e2bc-7bf3-476d-9f9b-038e1e3b5b22","order_type":"limit","size":"0.045","price":"18857.85","client_oid":"38641000-0000-0000-0000-636fd323e260","type":"received","side":"buy","product_id":"BTC-USD","time":"2022-09-26T03:54:17.858743Z","sequence":46724808807},{"price":"18857.85","order_id":"21d2e2bc-7bf3-476d-9f9b-038e1e3b5b22","remaining_size":"0.045","type":"open","side":"buy","product_id":"BTC-USD","time":"2022-09-26T03:54:17.858743Z","sequence":46724808808},{"order_id":"517f9254-2a02-4d1b-a11e-38398bef3674","order_type":"limit","size":"0.00084561","price":"18861.75","client_oid":"e00ceb9d-c474-46d8-d6c2-6b408852361b","type":"received","side":"sell","product_id":"BTC-USD","time":"2022-09-26T03:54:17.858840Z","sequence":46724808809},{"price":"18861.75","order_id":"517f9254-2a02-4d1b-a11e-38398bef3674","remaining_size":"0.00084561","type":"open","side":"sell","product_id":"BTC-USD","time":"2022-09-26T03:54:17.858840Z","sequence":46724808810},{"order_id":"cda19d56-4bbc-4513-b21f-c5e28d3e0df8","order_type":"limit","size":"0.02534887","price":"18861.17","client_oid":"00000000-0000-0000-0005-e958faec78e3","type":"received","side":"sell","product_id":"BTC-USD","time":"2022-09-26T03:54:17.858850Z","sequence":46724808811},{"price":"18861.17","order_id":"cda19d56-4bbc-4513-b21f-c5e28d3e0df8","remaining_size":"0.02534887","type":"open","side":"sell","product_id":"BTC-USD","time":"2022-09-26T03:54:17.858850Z","sequence":46724808812},{"order_id":"c73c1ae9-d12e-473b-b333-60d61fccfe07","order_type":"limit","size":"0.60390394","price":"18855.8","client_oid":"ea260deb-90b8-434b-87f5-fc259d214b03","type":"received","side":"buy","product_id":"BTC-USD","time":"2022-09-26T03:54:17.858890Z","sequence":46724808813},{"price":"18855.8","order_id":"c73c1ae9-d12e-473b-b333-60d61fccfe07","remaining_size":"0.60390394","type":"open","side":"buy","product_id":"BTC-USD","time":"2022-09-26T03:54:17.858890Z","sequence":46724808814},{"order_id":"463fc057-26bd-4cfe-b60b-1a16095b70fb","order_type":"limit","size":"0.02534887","price":"18856.36","client_oid":"00000000-0000-0000-0005-e958faec78e2","type":"received","side":"buy","product_id":"BTC-USD","time":"2022-09-26T03:54:17.858928Z","sequence":46724808815},{"price":"18856.36","order_id":"463fc057-26bd-4cfe-b60b-1a16095b70fb","remaining_size":"0.02534887","type":"open","side":"buy","product_id":"BTC-USD","time":"2022-09-26T03:54:17.858928Z","sequence":46724808816},{"order_id":"5ecebef3-7964-41f3-a9b2-9c228b084f3f","order_type":"limit","size":"0.05167328","price":"18856.16","client_oid":"c8388213-d2d4-4a41-876b-16916a8cdc32","type":"received","side":"buy","product_id":"BTC-USD","time":"2022-09-26T03:54:17.858943Z","sequence":46724808817},{"price":"18856.16","order_id":"5ecebef3-7964-41f3-a9b2-9c228b084f3f","remaining_size":"0.05167328","type":"open","side":"buy","product_id":"BTC-USD","time":"2022-09-26T03:54:17.858943Z","sequence":46724808818},{"order_id":"6b76f89d-fe6b-4d92-91c6-69df86d33321","order_type":"limit","size":"0.34013623","price":"18867.1","client_oid":"a343f7da-4f7a-4060-b3d9-e6f4c2e2eee2","type":"received","side":"sell","product_id":"BTC-USD","time":"2022-09-26T03:54:17.858952Z","sequence":46724808819},{"price":"18867.1","order_id":"6b76f89d-fe6b-4d92-91c6-69df86d33321","remaining_size":"0.34013623","type":"open","side":"sell","product_id":"BTC-USD","time":"2022-09-26T03:54:17.858952Z","sequence":46724808820},{"order_id":"01355b41-be92-4695-87b9-ebbb33d08ef8","reason":"canceled","price":"18862.11","remaining_size":"0.04432671","type":"done","side":"sell","product_id":"BTC-USD","time":"2022-09-26T03:54:17.863632Z","sequence":46724808821},{"order_id":"610fba05-094d-48de-8349-c9edee5de2d4","order_type":"limit","size":"0.02417","price":"18859.03","client_oid":"20220926-0000-0000-0001-000000209808","type":"received","side":"buy","product_id":"BTC-USD","time":"2022-09-26T03:54:17.867069Z","sequence":46724808822},{"price":"18859.03","order_id":"610fba05-094d-48de-8349-c9edee5de2d4","remaining_size":"0.02417","type":"open","side":"buy","product_id":"BTC-USD","time":"2022-09-26T03:54:17.867069Z","sequence":46724808823},{"order_id":"c7dd6f13-3ba3-40ab-ab25-c0016a73ecf7","reason":"canceled","price":"18861.83","remaining_size":"0.09741957","type":"done","side":"sell","product_id":"BTC-USD","time":"2022-09-26T03:54:17.869250Z","sequence":46724808824},{"order_id":"8f21fe3e-4302-464a-832d-ec94f6d478ab","order_type":"limit","size":"0.00102862","price":"18861.55","client_oid":"e8f7baa4-e54e-6e4d-00a2-1d34322f9c6f","type":"received","side":"sell","product_id":"BTC-USD","time":"2022-09-26T03:54:17.870778Z","sequence":46724808825},{"price":"18861.55","order_id":"8f21fe3e-4302-464a-832d-ec94f6d478ab","remaining_size":"0.00102862","type":"open","side":"sell","product_id":"BTC-USD","time":"2022-09-26T03:54:17.870778Z","sequence":46724808826},{"order_id":"2d6edebc-6eb9-483a-af7d-e4280b5d4583","reason":"canceled","price":"18862.51","remaining_size":"0.39009828","type":"done","side":"sell","product_id":"BTC-USD","time":"2022-09-26T03:54:17.872238Z","sequence":46724808827},{"order_id":"5d0d9fea-6977-4507-9a91-52fd77c1fc81","reason":"canceled","price":"18835","remaining_size":"1.71","type":"done","side":"buy","product_id":"BTC-USD","time":"2022-09-26T03:54:17.873389Z","sequence":46724808828},{"order_id":"bd46e560-4303-40d3-aee6-edeba4de4eaa","reason":"canceled","price":"18857.7","remaining_size":"0.05","type":"done","side":"buy","product_id":"BTC-USD","time":"2022-09-26T03:54:17.873536Z","sequence":46724808829},{"order_id":"21d2e2bc-7bf3-476d-9f9b-038e1e3b5b22","reason":"canceled","price":"18857.85","remaining_size":"0.045","type":"done","side":"buy","product_id":"BTC-USD","time":"2022-09-26T03:54:17.873679Z","sequence":46724808830},{"order_id":"8f21fe3e-4302-464a-832d-ec94f6d478ab","reason":"canceled","price":"18861.55","remaining_size":"0.00102862","type":"done","side":"sell","product_id":"BTC-USD","time":"2022-09-26T03:54:17.873815Z","sequence":46724808831},{"order_id":"a814d636-fff2-4a66-85e9-ef109061c649","order_type":"limit","size":"0.03105993","price":"18857.87","client_oid":"9501ba6f-3166-d72c-465d-f21c5ef26528","type":"received","side":"buy","product_id":"BTC-USD","time":"2022-09-26T03:54:17.874794Z","sequence":46724808832},{"price":"18857.87","order_id":"a814d636-fff2-4a66-85e9-ef109061c649","remaining_size":"0.03105993","type":"open","side":"buy","product_id":"BTC-USD","time":"2022-09-26T03:54:17.874794Z","sequence":46724808833},{"order_id":"096addc0-0cd7-4c5d-8d94-4b7176886c3f","order_type":"limit","size":"0.06","price":"18859.03","client_oid":"20220926-0000-0000-0003-000000024729","type":"received","side":"buy","product_id":"BTC-USD","time":"2022-09-26T03:54:17.874809Z","sequence":46724808834},{"price":"18859.03","order_id":"096addc0-0cd7-4c5d-8d94-4b7176886c3f","remaining_size":"0.06","type":"open","side":"buy","product_id":"BTC-USD","time":"2022-09-26T03:54:17.874809Z","sequence":46724808835},{"order_id":"463fc057-26bd-4cfe-b60b-1a16095b70fb","reason":"canceled","price":"18856.36","remaining_size":"0.02534887","type":"done","side":"buy","product_id":"BTC-USD","time":"2022-09-26T03:54:17.876560Z","sequence":46724808836},{"order_id":"950ba279-867f-4f3f-8ff3-00c1baf02845","order_type":"limit","size":"0.05","price":"18859.03","client_oid":"d98be479-1238-1803-9c5f-33dfc14c1817","type":"received","side":"buy","product_id":"BTC-USD","time":"2022-09-26T03:54:17.878781Z","sequence":46724808837},{"price":"18859.03","order_id":"950ba279-867f-4f3f-8ff3-00c1baf02845","remaining_size":"0.05","type":"open","side":"buy","product_id":"BTC-USD","time":"2022-09-26T03:54:17.878781Z","sequence":46724808838},{"order_id":"1b16b8f5-c682-4d7a-9c8c-1ceac4266df3","order_type":"limit","size":"0.045","price":"18859.03","client_oid":"38641000-0000-0000-0000-636fd32400cb","type":"received","side":"buy","product_id":"BTC-USD","time":"2022-09-26T03:54:17.878931Z","sequence":46724808839},{"price":"18859.03","order_id":"1b16b8f5-c682-4d7a-9c8c-1ceac4266df3","remaining_size":"0.045","type":"open","side":"buy","product_id":"BTC-USD","time":"2022-09-26T03:54:17.878931Z","sequence":46724808840},{"order_id":"8d174d78-c818-4cf4-8ad3-018831dd5170","order_type":"limit","size":"0.02534887","price":"18856.72","client_oid":"00000000-0000-0000-0005-e958faec78e4","type":"received","side":"buy","product_id":"BTC-USD","time":"2022-09-26T03:54:17.879251Z","sequence":46724808841},{"price":"18856.72","order_id":"8d174d78-c818-4cf4-8ad3-018831dd5170","remaining_size":"0.02534887","type":"open","side":"buy","product_id":"BTC-USD","time":"2022-09-26T03:54:17.879251Z","sequence":46724808842},{"order_id":"8d174d78-c818-4cf4-8ad3-018831dd5170","reason":"canceled","price":"18856.72","remaining_size":"0.02534887","type":"done","side":"buy","product_id":"BTC-USD","time":"2022-09-26T03:54:17.884946Z","sequence":46724808843},{"order_id":"e9082e06-cea7-4fb7-aaa7-083c206253a3","reason":"canceled","price":"18859.04","remaining_size":"0.04432671","type":"done","side":"sell","product_id":"BTC-USD","time":"2022-09-26T03:54:17.885184Z","sequence":46724808844},{"order_id":"59e097e3-6b6e-46f4-aea8-65ee48615979","order_type":"limit","size":"0.08","price":"18856.67","client_oid":"20220926-0000-0000-0060-000000203685","type":"received","side":"buy","product_id":"BTC-USD","time":"2022-09-26T03:54:17.887151Z","sequence":46724808845},{"price":"18856.67","order_id":"59e097e3-6b6e-46f4-aea8-65ee48615979","remaining_size":"0.08","type":"open","side":"buy","product_id":"BTC-USD","time":"2022-09-26T03:54:17.887151Z","sequence":46724808846},{"order_id":"5ecebef3-7964-41f3-a9b2-9c228b084f3f","reason":"canceled","price":"18856.16","remaining_size":"0.05167328","type":"done","side":"buy","product_id":"BTC-USD","time":"2022-09-26T03:54:17.889222Z","sequence":46724808847},{"order_id":"cda19d56-4bbc-4513-b21f-c5e28d3e0df8","reason":"canceled","price":"18861.17","remaining_size":"0.02534887","type":"done","side":"sell","product_id":"BTC-USD","time":"2022-09-26T03:54:17.890032Z","sequence":46724808848},{"order_id":"e04dafb4-4dce-4d00-b741-fd5530ab668c","reason":"canceled","price":"18863.09","remaining_size":"0.62182875","type":"done","side":"sell","product_id":"BTC-USD","time":"2022-09-26T03:54:17.890307Z","sequence":46724808849},{"order_id":"610fba05-094d-48de-8349-c9edee5de2d4","reason":"canceled","price":"18859.03","remaining_size":"0.02417","type":"done","side":"buy","product_id":"BTC-USD","time":"2022-09-26T03:54:17.890454Z","sequence":46724808850},{"order_id":"2397b15d-527f-4090-badb-38572e024980","order_type":"limit","size":"0.02534887","price":"18857.07","client_oid":"00000000-0000-0000-0005-e958faec78eb","type":"received","side":"buy","product_id":"BTC-USD","time":"2022-09-26T03:54:17.891260Z","sequence":46724808851},{"price":"18857.07","order_id":"2397b15d-527f-4090-badb-38572e024980","remaining_size":"0.02534887","type":"open","side":"buy","product_id":"BTC-USD","time":"2022-09-26T03:54:17.891260Z","sequence":46724808852},{"order_id":"e7b5c178-35fc-44bd-be78-0f6da694f728","reason":"canceled","price":"18862.62","remaining_size":"0.08","type":"done","side":"sell","product_id":"BTC-USD","time":"2022-09-26T03:54:17.892629Z","sequence":46724808853},{"order_id":"c8917086-d768-4db3-ba5f-9cc18b3dbbcd","reason":"canceled","price":"18862.35","remaining_size":"0.1","type":"done","side":"sell","product_id":"BTC-USD","time":"2022-09-26T03:54:17.894122Z","sequence":46724808854},{"order_id":"ff8ba492-7a96-432e-b200-92457548b74b","order_type":"limit","size":"0.3763055","price":"18863.09","client_oid":"4e00b0a4-76fc-4780-85ff-0865fc96d252","type":"received","side":"sell","product_id":"BTC-USD","time":"2022-09-26T03:54:17.894840Z","sequence":46724808855},{"price":"18863.09","order_id":"ff8ba492-7a96-432e-b200-92457548b74b","remaining_size":"0.3763055","type":"open","side":"sell","product_id":"BTC-USD","time":"2022-09-26T03:54:17.894840Z","sequence":46724808856},{"order_id":"b46b2043-275a-4b90-ae3a-44566255aedf","order_type":"limit","size":"0.02534887","price":"18862.18","client_oid":"00000000-0000-0000-0005-e958faec78ed","type":"received","side":"sell","product_id":"BTC-USD","time":"2022-09-26T03:54:17.894957Z","sequence":46724808857},{"price":"18862.18","order_id":"b46b2043-275a-4b90-ae3a-44566255aedf","remaining_size":"0.02534887","type":"open","side":"sell","product_id":"BTC-USD","time":"2022-09-26T03:54:17.894957Z","sequence":46724808858},{"order_id":"d7ab3773-59dd-438c-a494-1be8f2f0c0cd","order_type":"limit","size":"0.37980402","price":"18862.79","client_oid":"9b768709-ca49-4ee0-9193-c715ea4f4f3a","type":"received","side":"sell","product_id":"BTC-USD","time":"2022-09-26T03:54:17.895133Z","sequence":46724808859},{"price":"18862.79","order_id":"d7ab3773-59dd-438c-a494-1be8f2f0c0cd","remaining_size":"0.37980402","type":"open","side":"sell","product_id":"BTC-USD","time":"2022-09-26T03:54:17.895133Z","sequence":46724808860},{"order_id":"11740ae9-022f-498c-94c4-1076f859f5af","order_type":"limit","size":"0.02417","price":"18859.46","client_oid":"20220926-0000-0000-0002-000000215304","type":"received","side":"buy","product_id":"BTC-USD","time":"2022-09-26T03:54:17.895184Z","sequence":46724808861},{"price":"18859.46","order_id":"11740ae9-022f-498c-94c4-1076f859f5af","remaining_size":"0.02417","type":"open","side":"buy","product_id":"BTC-USD","time":"2022-09-26T03:54:17.895184Z","sequence":46724808862},{"order_id":"2397b15d-527f-4090-badb-38572e024980","reason":"canceled","price":"18857.07","remaining_size":"0.02534887","type":"done","side":"buy","product_id":"BTC-USD","time":"2022-09-26T03:54:17.895970Z","sequence":46724808863},{"order_id":"11740ae9-022f-498c-94c4-1076f859f5af","reason":"canceled","price":"18859.46","remaining_size":"0.02417","type":"done","side":"buy","product_id":"BTC-USD","time":"2022-09-26T03:54:17.899280Z","sequence":46724808864},{"order_id":"42c93fc4-7e77-47a5-8e30-c3bb03031615","order_type":"limit","size":"0.07962139","price":"18859.03","client_oid":"5eb1efbb-559d-4fd3-9b43-7ab3523684b5","type":"received","side":"buy","product_id":"BTC-USD","time":"2022-09-26T03:54:17.899680Z","sequence":46724808865},{"price":"18859.03","order_id":"42c93fc4-7e77-47a5-8e30-c3bb03031615","remaining_size":"0.07962139","type":"open","side":"buy","product_id":"BTC-USD","time":"2022-09-26T03:54:17.899680Z","sequence":46724808866},{"order_id":"464049ee-6437-4246-9f3f-7973241d4c87","order_type":"limit","size":"0.06","price":"18859.46","client_oid":"20220926-0000-0000-0004-000000024754","type":"received","side":"buy","product_id":"BTC-USD","time":"2022-09-26T03:54:17.900144Z","sequence":46724808867},{"price":"18859.46","order_id":"464049ee-6437-4246-9f3f-7973241d4c87","remaining_size":"0.06","type":"open","side":"buy","product_id":"BTC-USD","time":"2022-09-26T03:54:17.900144Z","sequence":46724808868},{"order_id":"c45ceee4-db71-4a1e-ab4e-f249fdb081df","order_type":"limit","size":"0.02534887","price":"18857.22","client_oid":"00000000-0000-0000-0005-e958faec78ee","type":"received","side":"buy","product_id":"BTC-USD","time":"2022-09-26T03:54:17.900157Z","sequence":46724808869},{"price":"18857.22","order_id":"c45ceee4-db71-4a1e-ab4e-f249fdb081df","remaining_size":"0.02534887","type":"open","side":"buy","product_id":"BTC-USD","time":"2022-09-26T03:54:17.900157Z","sequence":46724808870},{"order_id":"096addc0-0cd7-4c5d-8d94-4b7176886c3f","reason":"canceled","price":"18859.03","remaining_size":"0.06","type":"done","side":"buy","product_id":"BTC-USD","time":"2022-09-26T03:54:17.901087Z","sequence":46724808871},{"order_id":"02934e96-cfdf-45cb-8fa9-381122c26dc6","reason":"canceled","price":"18866.71","remaining_size":"0.875","type":"done","side":"sell","product_id":"BTC-USD","time":"2022-09-26T03:54:17.901494Z","sequence":46724808872},{"order_id":"d4b63159-8ceb-4376-a8fe-b5dd0f7fc515","reason":"canceled","price":"18847.47","remaining_size":"0.875","type":"done","side":"buy","product_id":"BTC-USD","time":"2022-09-26T03:54:17.901707Z","sequence":46724808873},{"order_id":"f19f3413-185d-4dc2-8618-2ec3bcad530a","reason":"canceled","price":"18860.21","remaining_size":"0.00706675","type":"done","side":"sell","product_id":"BTC-USD","time":"2022-09-26T03:54:17.901741Z","sequence":46724808874},{"order_id":"1b16b8f5-c682-4d7a-9c8c-1ceac4266df3","reason":"canceled","price":"18859.03","remaining_size":"0.045","type":"done","side":"buy","product_id":"BTC-USD","time":"2022-09-26T03:54:17.901975Z","sequence":46724808875},{"order_id":"f2003a7e-f817-41e6-a674-3c29fe343e25","reason":"canceled","price":"18859.03","remaining_size":"0.00228234","type":"done","side":"buy","product_id":"BTC-USD","time":"2022-09-26T03:54:17.903883Z","sequence":46724808876},{"order_id":"5ed0ab98-6df6-448e-b522-ada04ce2efd3","order_type":"limit","size":"0.03041032","price":"18849.74","client_oid":"e51c16bd-3d4e-11ed-8b5d-abb0b41c20d0","type":"received","side":"buy","product_id":"BTC-USD","time":"2022-09-26T03:54:17.904227Z","sequence":46724808877},{"price":"18849.74","order_id":"5ed0ab98-6df6-448e-b522-ada04ce2efd3","remaining_size":"0.03041032","type":"open","side":"buy","product_id":"BTC-USD","time":"2022-09-26T03:54:17.904227Z","sequence":46724808878},{"order_id":"b46b2043-275a-4b90-ae3a-44566255aedf","reason":"canceled","price":"18862.18","remaining_size":"0.02534887","type":"done","side":"sell","product_id":"BTC-USD","time":"2022-09-26T03:54:17.904299Z","sequence":46724808879},{"order_id":"517f9254-2a02-4d1b-a11e-38398bef3674","reason":"canceled","price":"18861.75","remaining_size":"0.00084561","type":"done","side":"sell","product_id":"BTC-USD","time":"2022-09-26T03:54:17.904973Z","sequence":46724808880},{"order_id":"c45ceee4-db71-4a1e-ab4e-f249fdb081df","reason":"canceled","price":"18857.22","remaining_size":"0.02534887","type":"done","side":"buy","product_id":"BTC-USD","time":"2022-09-26T03:54:17.906133Z","sequence":46724808881},{"order_id":"a57b36bb-1578-4d43-8f27-4577fa473a2e","order_type":"limit","size":"0.045","price":"18859.46","client_oid":"48641000-0000-0000-0000-636fd323eee7","type":"received","side":"buy","product_id":"BTC-USD","time":"2022-09-26T03:54:17.909064Z","sequence":46724808882},{"price":"18859.46","order_id":"a57b36bb-1578-4d43-8f27-4577fa473a2e","remaining_size":"0.045","type":"open","side":"buy","product_id":"BTC-USD","time":"2022-09-26T03:54:17.909064Z","sequence":46724808883},{"order_id":"12cea405-ab32-4379-9d6e-af48ae7309c3","reason":"canceled","price":"18860.2","remaining_size":"0.004","type":"done","side":"sell","product_id":"BTC-USD","time":"2022-09-26T03:54:17.909663Z","sequence":46724808884},{"order_id":"d22d2f1d-4ede-4de0-9841-1a6f50e8bda7","order_type":"limit","size":"0.00574054","price":"18861.71","client_oid":"df1435e6-2cc5-5748-de99-40754b1184f9","type":"received","side":"sell","product_id":"BTC-USD","time":"2022-09-26T03:54:17.912356Z","sequence":46724808885},{"price":"18861.71","order_id":"d22d2f1d-4ede-4de0-9841-1a6f50e8bda7","remaining_size":"0.00574054","type":"open","side":"sell","product_id":"BTC-USD","time":"2022-09-26T03:54:17.912356Z","sequence":46724808886},{"order_id":"fdf0612e-4c01-4a0d-8113-83d627cac267","order_type":"limit","size":"0.00228234","price":"18859.46","client_oid":"e51d7d7b-3d4e-11ed-8a20-0aa09ad95c5f","type":"received","side":"buy","product_id":"BTC-USD","time":"2022-09-26T03:54:17.912431Z","sequence":46724808887},{"price":"18859.46","order_id":"fdf0612e-4c01-4a0d-8113-83d627cac267","remaining_size":"0.00228234","type":"open","side":"buy","product_id":"BTC-USD","time":"2022-09-26T03:54:17.912431Z","sequence":46724808888},{"order_id":"cda712eb-4a75-4c40-895f-82473c9f53c9","order_type":"limit","size":"0.15832586","price":"18863.45","client_oid":"e51d7653-3d4e-11ed-8b5d-abb0b41c20d0","type":"received","side":"sell","product_id":"BTC-USD","time":"2022-09-26T03:54:17.912594Z","sequence":46724808889},{"price":"18863.45","order_id":"cda712eb-4a75-4c40-895f-82473c9f53c9","remaining_size":"0.15832586","type":"open","side":"sell","product_id":"BTC-USD","time":"2022-09-26T03:54:17.912594Z","sequence":46724808890},{"order_id":"beb6babb-70b5-42db-8528-ffe67415b0d1","order_type":"limit","size":"0.02196434","price":"18859.08","client_oid":"e8d72fa8-c833-f545-5b98-4e3788aacdba","type":"received","side":"buy","product_id":"BTC-USD","time":"2022-09-26T03:54:17.912607Z","sequence":46724808891},{"price":"18859.08","order_id":"beb6babb-70b5-42db-8528-ffe67415b0d1","remaining_size":"0.02196434","type":"open","side":"buy","product_id":"BTC-USD","time":"2022-09-26T03:54:17.912607Z","sequence":46724808892},{"order_id":"f2a8f141-c595-4338-a951-c804eb473ea3","order_type":"limit","size":"0.02534887","price":"18857.63","client_oid":"00000000-0000-0000-0005-e958faec78f2","type":"received","side":"buy","product_id":"BTC-USD","time":"2022-09-26T03:54:17.912617Z","sequence":46724808893},{"price":"18857.63","order_id":"f2a8f141-c595-4338-a951-c804eb473ea3","remaining_size":"0.02534887","type":"open","side":"buy","product_id":"BTC-USD","time":"2022-09-26T03:54:17.912617Z","sequence":46724808894},{"order_id":"8b8b016d-81e4-4b13-b801-e8453efa6557","order_type":"limit","size":"0.02534887","price":"18862.03","client_oid":"00000000-0000-0000-0005-e958faec78f1","type":"received","side":"sell","product_id":"BTC-USD","time":"2022-09-26T03:54:17.912933Z","sequence":46724808895},{"price":"18862.03","order_id":"8b8b016d-81e4-4b13-b801-e8453efa6557","remaining_size":"0.02534887","type":"open","side":"sell","product_id":"BTC-USD","time":"2022-09-26T03:54:17.912933Z","sequence":46724808896},{"order_id":"3dcf9d90-6f99-4bb7-bfac-2b3762ec50a2","order_type":"limit","size":"0.02534887","price":"18862.17","client_oid":"00000000-0000-0000-0005-e958faec78f6","type":"received","side":"sell","product_id":"BTC-USD","time":"2022-09-26T03:54:17.916585Z","sequence":46724808897},{"price":"18862.17","order_id":"3dcf9d90-6f99-4bb7-bfac-2b3762ec50a2","remaining_size":"0.02534887","type":"open","side":"sell","product_id":"BTC-USD","time":"2022-09-26T03:54:17.916585Z","sequence":46724808898},{"order_id":"8e79c42b-81d8-4881-93f4-50896509937a","order_type":"limit","size":"0.04181544","price":"18857.25","client_oid":"4ca81c03-9c7b-5700-b6ec-a039de2c0592","type":"received","side":"buy","product_id":"BTC-USD","time":"2022-09-26T03:54:17.916598Z","sequence":46724808899},{"price":"18857.25","order_id":"8e79c42b-81d8-4881-93f4-50896509937a","remaining_size":"0.04181544","type":"open","side":"buy","product_id":"BTC-USD","time":"2022-09-26T03:54:17.916598Z","sequence":46724808900}]